Workbook

Sheet Doctor Summary
A1: Baby Tracker: Pediatrician Summary | Z1: =B5-6 -> 46306
A2: Averages per day from the baby tracker app. Full days only; days run 4 AM to 4 AM. | Z2: =B5 -> 46312
A4: Birth date | B4: 46121 | C4: From the app's Profile; edit if needed
A5: Report date (last full day) | B5: =_xlfn.MAXIFS('Daily Summary'!$A$5:$A$70,'Daily Summary'!$C$5:$C$70,"Yes") -> 46312
A6: Age on report date | B6: =DATEDIF(B4,B5,"m")&" months, "&(B5-EDATE(B4,DATEDIF(B4,B5,"m")))&" days" -> 6 months, 8 days
A7: Tracking since | B7: =MIN('Daily Summary'!$A$5:$A$70) -> 46248
A9: ="Last 7 days = "&TEXT(Z1,"mmm d")&" to "&TEXT(Z2,"mmm d")&". Previous 7 days = "&TEXT(Z1-7,"mmm d")&" to "&TEXT(Z1-1,"mmm d")&"." -> Last 7 days = Oct 11 to Oct 17. Previous 7 days = Oct 4 to Oct 10.
A10: Per day (average) | B10: Last 7 days | C10: Previous 7 days | D10: Change
A11: Feeds | B11: =IFERROR(AVERAGEIFS('Daily Summary'!$D$5:$D$70,'Daily Summary'!$A$5:$A$70,">="&$Z$1,'Daily Summary'!$A$5:$A$70,"<="&$Z$2,'Daily Summary'!$C$5:$C$70,"Yes"),"") -> 5.7142857 | C11: =IFERROR(AVERAGEIFS('Daily Summary'!$D$5:$D$70,'Daily Summary'!$A$5:$A$70,">="&$Z$1-7,'Daily Summary'!$A$5:$A$70,"<="&$Z$1-1,'Daily Summary'!$C$5:$C$70,"Yes"),"") -> 5.5714286 | D11: =IF(OR(B11="",C11=""),"",B11-C11) -> 0.14285714
A12: Ounces | B12: =IFERROR(AVERAGEIFS('Daily Summary'!$F$5:$F$70,'Daily Summary'!$A$5:$A$70,">="&$Z$1,'Daily Summary'!$A$5:$A$70,"<="&$Z$2,'Daily Summary'!$C$5:$C$70,"Yes"),"") -> 29.285714 | C12: =IFERROR(AVERAGEIFS('Daily Summary'!$F$5:$F$70,'Daily Summary'!$A$5:$A$70,">="&$Z$1-7,'Daily Summary'!$A$5:$A$70,"<="&$Z$1-1,'Daily Summary'!$C$5:$C$70,"Yes"),"") -> 28.857143 | D12: =IF(OR(B12="",C12=""),"",B12-C12) -> 0.42857143
A13: Ounces per feed | B13: =IFERROR(SUMIFS('Daily Summary'!$F$5:$F$70,'Daily Summary'!$A$5:$A$70,">="&$Z$1,'Daily Summary'!$A$5:$A$70,"<="&$Z$2,'Daily Summary'!$C$5:$C$70,"Yes")/SUMIFS('Daily Summary'!$E$5:$E$70,'Daily Summary'!$A$5:$A$70,">="&$Z$1,'Daily Summary'!$A$5:$A$70,"<="&$Z$2,'Daily Summary'!$C$5:$C$70,"Yes"),"") -> 5.125 | C13: =IFERROR(SUMIFS('Daily Summary'!$F$5:$F$70,'Daily Summary'!$A$5:$A$70,">="&$Z$1-7,'Daily Summary'!$A$5:$A$70,"<="&$Z$1-1,'Daily Summary'!$C$5:$C$70,"Yes")/SUMIFS('Daily Summary'!$E$5:$E$70,'Daily Summary'!$A$5:$A$70,">="&$Z$1-7,'Daily Summary'!$A$5:$A$70,"<="&$Z$1-1,'Daily Summary'!$C$5:$C$70,"Yes"),"") -> 5.1794872 | D13: =IF(OR(B13="",C13=""),"",B13-C13) -> -0.054487179
A14: Wet diapers | B14: =IFERROR(AVERAGEIFS('Daily Summary'!$H$5:$H$70,'Daily Summary'!$A$5:$A$70,">="&$Z$1,'Daily Summary'!$A$5:$A$70,"<="&$Z$2,'Daily Summary'!$C$5:$C$70,"Yes"),"") -> 4.2857143 | C14: =IFERROR(AVERAGEIFS('Daily Summary'!$H$5:$H$70,'Daily Summary'!$A$5:$A$70,">="&$Z$1-7,'Daily Summary'!$A$5:$A$70,"<="&$Z$1-1,'Daily Summary'!$C$5:$C$70,"Yes"),"") -> 4.5714286 | D14: =IF(OR(B14="",C14=""),"",B14-C14) -> -0.28571429
A15: Dirty diapers | B15: =IFERROR(AVERAGEIFS('Daily Summary'!$I$5:$I$70,'Daily Summary'!$A$5:$A$70,">="&$Z$1,'Daily Summary'!$A$5:$A$70,"<="&$Z$2,'Daily Summary'!$C$5:$C$70,"Yes"),"") -> 1.1428571 | C15: =IFERROR(AVERAGEIFS('Daily Summary'!$I$5:$I$70,'Daily Summary'!$A$5:$A$70,">="&$Z$1-7,'Daily Summary'!$A$5:$A$70,"<="&$Z$1-1,'Daily Summary'!$C$5:$C$70,"Yes"),"") -> 0.85714286 | D15: =IF(OR(B15="",C15=""),"",B15-C15) -> 0.28571429
A16: Naps | B16: =IFERROR(AVERAGEIFS('Daily Summary'!$L$5:$L$70,'Daily Summary'!$A$5:$A$70,">="&$Z$1,'Daily Summary'!$A$5:$A$70,"<="&$Z$2,'Daily Summary'!$C$5:$C$70,"Yes"),"") -> 4 | C16: =IFERROR(AVERAGEIFS('Daily Summary'!$L$5:$L$70,'Daily Summary'!$A$5:$A$70,">="&$Z$1-7,'Daily Summary'!$A$5:$A$70,"<="&$Z$1-1,'Daily Summary'!$C$5:$C$70,"Yes"),"") -> 4.1428571 | D16: =IF(OR(B16="",C16=""),"",B16-C16) -> -0.14285714
A17: Nap hours | B17: =IFERROR(AVERAGEIFS('Daily Summary'!$M$5:$M$70,'Daily Summary'!$A$5:$A$70,">="&$Z$1,'Daily Summary'!$A$5:$A$70,"<="&$Z$2,'Daily Summary'!$C$5:$C$70,"Yes"),"") -> 3.102381 | C17: =IFERROR(AVERAGEIFS('Daily Summary'!$M$5:$M$70,'Daily Summary'!$A$5:$A$70,">="&$Z$1-7,'Daily Summary'!$A$5:$A$70,"<="&$Z$1-1,'Daily Summary'!$C$5:$C$70,"Yes"),"") -> 3.0928571 | D17: =IF(OR(B17="",C17=""),"",B17-C17) -> 0.0095238094
A18: Night sleep hours | B18: =IFERROR(AVERAGEIFS('Daily Summary'!$P$5:$P$70,'Daily Summary'!$A$5:$A$70,">="&$Z$1,'Daily Summary'!$A$5:$A$70,"<="&$Z$2,'Daily Summary'!$C$5:$C$70,"Yes"),"") -> 7.1309524 | C18: =IFERROR(AVERAGEIFS('Daily Summary'!$P$5:$P$70,'Daily Summary'!$A$5:$A$70,">="&$Z$1-7,'Daily Summary'!$A$5:$A$70,"<="&$Z$1-1,'Daily Summary'!$C$5:$C$70,"Yes"),"") -> 7.7119048 | D18: =IF(OR(B18="",C18=""),"",B18-C18) -> -0.58095238
A19: Total sleep hours | B19: =IFERROR(AVERAGEIFS('Daily Summary'!$Q$5:$Q$70,'Daily Summary'!$A$5:$A$70,">="&$Z$1,'Daily Summary'!$A$5:$A$70,"<="&$Z$2,'Daily Summary'!$C$5:$C$70,"Yes"),"") -> 10.233333 | C19: =IFERROR(AVERAGEIFS('Daily Summary'!$Q$5:$Q$70,'Daily Summary'!$A$5:$A$70,">="&$Z$1-7,'Daily Summary'!$A$5:$A$70,"<="&$Z$1-1,'Daily Summary'!$C$5:$C$70,"Yes"),"") -> 10.804762 | D19: =IF(OR(B19="",C19=""),"",B19-C19) -> -0.57142857
A20: Bedtime | B20: =IFERROR(MOD(AVERAGEIFS('Daily Summary'!$S$5:$S$70,'Daily Summary'!$A$5:$A$70,">="&$Z$1,'Daily Summary'!$A$5:$A$70,"<="&$Z$2,'Daily Summary'!$C$5:$C$70,"Yes")/24+0.5,1),"") -> 0.04781746 | C20: =IFERROR(MOD(AVERAGEIFS('Daily Summary'!$S$5:$S$70,'Daily Summary'!$A$5:$A$70,">="&$Z$1-7,'Daily Summary'!$A$5:$A$70,"<="&$Z$1-1,'Daily Summary'!$C$5:$C$70,"Yes")/24+0.5,1),"") -> 0.030853175 | D20: =IF(OR(B20="",C20=""),"",TEXT(ABS(B20-C20)*1440,"0")&" min "&IF(B20>C20,"later","earlier")) -> 24 min later
A21: Wake-up | B21: =IFERROR(AVERAGEIFS('Daily Summary'!$T$5:$T$70,'Daily Summary'!$A$5:$A$70,">="&$Z$1,'Daily Summary'!$A$5:$A$70,"<="&$Z$2,'Daily Summary'!$C$5:$C$70,"Yes"),"") -> 0.34494048 | C21: =IFERROR(AVERAGEIFS('Daily Summary'!$T$5:$T$70,'Daily Summary'!$A$5:$A$70,">="&$Z$1-7,'Daily Summary'!$A$5:$A$70,"<="&$Z$1-1,'Daily Summary'!$C$5:$C$70,"Yes"),"") -> 0.35218254 | D21: =IF(OR(B21="",C21=""),"",TEXT(ABS(B21-C21)*1440,"0")&" min "&IF(B21>C21,"later","earlier")) -> 10 min earlier
A22: Medicine doses | B22: =IFERROR(AVERAGEIFS('Daily Summary'!$R$5:$R$70,'Daily Summary'!$A$5:$A$70,">="&$Z$1,'Daily Summary'!$A$5:$A$70,"<="&$Z$2,'Daily Summary'!$C$5:$C$70,"Yes"),"") -> 2.8571429 | C22: =IFERROR(AVERAGEIFS('Daily Summary'!$R$5:$R$70,'Daily Summary'!$A$5:$A$70,">="&$Z$1-7,'Daily Summary'!$A$5:$A$70,"<="&$Z$1-1,'Daily Summary'!$C$5:$C$70,"Yes"),"") -> 2.8571429 | D22: =IF(OR(B22="",C22=""),"",B22-C22) -> 0
A24: Diapers: wet = pee or both, dirty = poop or both. Ounces were first logged on Aug 25, so earlier days show no ounces. Sleep is paired from start/end taps; see Data Notes for anything left out.

Sheet Daily Summary
A1: Daily Summary
A2: One row per baby day (4 AM to 4 AM). Bedtime and the next morning's wake-up belong to the day she went to bed. Yellow rows are partial days and are left out of weekly and doctor averages.
A4: Date | B4: Week of | C4: Include in averages | D4: Feeds | E4: Feeds with oz logged | F4: Total oz | G4: Avg oz per feed | H4: Wet diapers | I4: Dirty diapers | J4: Total diapers | K4: Diaper type not logged | L4: Naps | M4: Nap hours | N4: Bedtime | O4: Woke up (next morning) | P4: Night sleep (hrs) | Q4: Total sleep (hrs) | R4: Medicine doses | S4: Bedtime (hrs after noon) | T4: Wake time of day
A5: 46248 | B5: =A5-WEEKDAY(A5,3) -> 46244 | C5: No | D5: =COUNTIFS('Raw Log'!$F$5:$F$1538,A5,'Raw Log'!$B$5:$B$1538,"Feed") -> 2 | E5: =COUNTIFS('Raw Log'!$F$5:$F$1538,A5,'Raw Log'!$B$5:$B$1538,"Feed",'Raw Log'!$C$5:$C$1538,">0") -> 0 | F5: =IF(E5=0,"",SUMIFS('Raw Log'!$C$5:$C$1538,'Raw Log'!$F$5:$F$1538,A5,'Raw Log'!$B$5:$B$1538,"Feed")) | G5: =IF(E5=0,"",F5/E5) | H5: =IF(K5=J5,"",COUNTIFS('Raw Log'!$F$5:$F$1538,A5,'Raw Log'!$B$5:$B$1538,"Diaper",'Raw Log'!$D$5:$D$1538,"Pee")+COUNTIFS('Raw Log'!$F$5:$F$1538,A5,'Raw Log'!$B$5:$B$1538,"Diaper",'Raw Log'!$D$5:$D$1538,"Both")) | I5: =IF(K5=J5,"",COUNTIFS('Raw Log'!$F$5:$F$1538,A5,'Raw Log'!$B$5:$B$1538,"Diaper",'Raw Log'!$D$5:$D$1538,"Poop")+COUNTIFS('Raw Log'!$F$5:$F$1538,A5,'Raw Log'!$B$5:$B$1538,"Diaper",'Raw Log'!$D$5:$D$1538,"Both")) | J5: =COUNTIFS('Raw Log'!$F$5:$F$1538,A5,'Raw Log'!$B$5:$B$1538,"Diaper") -> 1 | K5: =J5-COUNTIFS('Raw Log'!$F$5:$F$1538,A5,'Raw Log'!$B$5:$B$1538,"Diaper",'Raw Log'!$D$5:$D$1538,"Pee")-COUNTIFS('Raw Log'!$F$5:$F$1538,A5,'Raw Log'!$B$5:$B$1538,"Diaper",'Raw Log'!$D$5:$D$1538,"Poop")-COUNTIFS('Raw Log'!$F$5:$F$1538,A5,'Raw Log'!$B$5:$B$1538,"Diaper",'Raw Log'!$D$5:$D$1538,"Both") -> 1 | L5: =COUNTIFS('Sleep Detail'!$A$5:$A$285,A5,'Sleep Detail'!$B$5:$B$285,"Nap") -> 0 | M5: =SUMIFS('Sleep Detail'!$E$5:$E$285,'Sleep Detail'!$A$5:$A$285,A5,'Sleep Detail'!$B$5:$B$285,"Nap") -> 0 | N5: =IF(COUNTIFS('Sleep Detail'!$A$5:$A$285,A5,'Sleep Detail'!$B$5:$B$285,"Night")=0,"",_xlfn.MINIFS('Sleep Detail'!$C$5:$C$285,'Sleep Detail'!$A$5:$A$285,A5,'Sleep Detail'!$B$5:$B$285,"Night")) -> 46249.025 | O5: =IF(COUNTIFS('Sleep Detail'!$A$5:$A$285,A5,'Sleep Detail'!$B$5:$B$285,"Night")=0,"",_xlfn.MAXIFS('Sleep Detail'!$D$5:$D$285,'Sleep Detail'!$A$5:$A$285,A5,'Sleep Detail'!$B$5:$B$285,"Night")) -> 46249.312 | P5: =IF(COUNTIFS('Sleep Detail'!$A$5:$A$285,A5,'Sleep Detail'!$B$5:$B$285,"Night")=0,"",SUMIFS('Sleep Detail'!$E$5:$E$285,'Sleep Detail'!$A$5:$A$285,A5,'Sleep Detail'!$B$5:$B$285,"Night")) -> 6.9 | Q5: =IF(P5="","",M5+P5) -> 6.9 | R5: =COUNTIFS('Raw Log'!$F$5:$F$1538,A5,'Raw Log'!$B$5:$B$1538,"Medicine") -> 2 | S5: =IF(N5="","",MOD(N5-0.5,1)*24) -> 12.6 | T5: =IF(O5="","",MOD(O5,1)) -> 0.3125
A6: 46249 | B6: =A6-WEEKDAY(A6,3) -> 46244 | C6: Yes | D6: =COUNTIFS('Raw Log'!$F$5:$F$1538,A6,'Raw Log'!$B$5:$B$1538,"Feed") -> 7 | E6: =COUNTIFS('Raw Log'!$F$5:$F$1538,A6,'Raw Log'!$B$5:$B$1538,"Feed",'Raw Log'!$C$5:$C$1538,">0") -> 0 | F6: =IF(E6=0,"",SUMIFS('Raw Log'!$C$5:$C$1538,'Raw Log'!$F$5:$F$1538,A6,'Raw Log'!$B$5:$B$1538,"Feed")) | G6: =IF(E6=0,"",F6/E6) | H6: =IF(K6=J6,"",COUNTIFS('Raw Log'!$F$5:$F$1538,A6,'Raw Log'!$B$5:$B$1538,"Diaper",'Raw Log'!$D$5:$D$1538,"Pee")+COUNTIFS('Raw Log'!$F$5:$F$1538,A6,'Raw Log'!$B$5:$B$1538,"Diaper",'Raw Log'!$D$5:$D$1538,"Both")) | I6: =IF(K6=J6,"",COUNTIFS('Raw Log'!$F$5:$F$1538,A6,'Raw Log'!$B$5:$B$1538,"Diaper",'Raw Log'!$D$5:$D$1538,"Poop")+COUNTIFS('Raw Log'!$F$5:$F$1538,A6,'Raw Log'!$B$5:$B$1538,"Diaper",'Raw Log'!$D$5:$D$1538,"Both")) | J6: =COUNTIFS('Raw Log'!$F$5:$F$1538,A6,'Raw Log'!$B$5:$B$1538,"Diaper") -> 7 | K6: =J6-COUNTIFS('Raw Log'!$F$5:$F$1538,A6,'Raw Log'!$B$5:$B$1538,"Diaper",'Raw Log'!$D$5:$D$1538,"Pee")-COUNTIFS('Raw Log'!$F$5:$F$1538,A6,'Raw Log'!$B$5:$B$1538,"Diaper",'Raw Log'!$D$5:$D$1538,"Poop")-COUNTIFS('Raw Log'!$F$5:$F$1538,A6,'Raw Log'!$B$5:$B$1538,"Diaper",'Raw Log'!$D$5:$D$1538,"Both") -> 7 | L6: =COUNTIFS('Sleep Detail'!$A$5:$A$285,A6,'Sleep Detail'!$B$5:$B$285,"Nap") -> 6 | M6: =SUMIFS('Sleep Detail'!$E$5:$E$285,'Sleep Detail'!$A$5:$A$285,A6,'Sleep Detail'!$B$5:$B$285,"Nap") -> 4.7 | N6: =IF(COUNTIFS('Sleep Detail'!$A$5:$A$285,A6,'Sleep Detail'!$B$5:$B$285,"Night")=0,"",_xlfn.MINIFS('Sleep Detail'!$C$5:$C$285,'Sleep Detail'!$A$5:$A$285,A6,'Sleep Detail'!$B$5:$B$285,"Night")) -> 46250.062 | O6: =IF(COUNTIFS('Sleep Detail'!$A$5:$A$285,A6,'Sleep Detail'!$B$5:$B$285,"Night")=0,"",_xlfn.MAXIFS('Sleep Detail'!$D$5:$D$285,'Sleep Detail'!$A$5:$A$285,A6,'Sleep Detail'!$B$5:$B$285,"Night")) -> 46250.254 | P6: =IF(COUNTIFS('Sleep Detail'!$A$5:$A$285,A6,'Sleep Detail'!$B$5:$B$285,"Night")=0,"",SUMIFS('Sleep Detail'!$E$5:$E$285,'Sleep Detail'!$A$5:$A$285,A6,'Sleep Detail'!$B$5:$B$285,"Night")) -> 4.6 | Q6: =IF(P6="","",M6+P6) -> 9.3 | R6: =COUNTIFS('Raw Log'!$F$5:$F$1538,A6,'Raw Log'!$B$5:$B$1538,"Medicine") -> 3 | S6: =IF(N6="","",MOD(N6-0.5,1)*24) -> 13.5 | T6: =IF(O6="","",MOD(O6,1)) -> 0.25416667
A7: 46250 | B7: =A7-WEEKDAY(A7,3) -> 46244 | C7: Yes | D7: =COUNTIFS('Raw Log'!$F$5:$F$1538,A7,'Raw Log'!$B$5:$B$1538,"Feed") -> 5 | E7: =COUNTIFS('Raw Log'!$F$5:$F$1538,A7,'Raw Log'!$B$5:$B$1538,"Feed",'Raw Log'!$C$5:$C$1538,">0") -> 0 | F7: =IF(E7=0,"",SUMIFS('Raw Log'!$C$5:$C$1538,'Raw Log'!$F$5:$F$1538,A7,'Raw Log'!$B$5:$B$1538,"Feed")) | G7: =IF(E7=0,"",F7/E7) | H7: =IF(K7=J7,"",COUNTIFS('Raw Log'!$F$5:$F$1538,A7,'Raw Log'!$B$5:$B$1538,"Diaper",'Raw Log'!$D$5:$D$1538,"Pee")+COUNTIFS('Raw Log'!$F$5:$F$1538,A7,'Raw Log'!$B$5:$B$1538,"Diaper",'Raw Log'!$D$5:$D$1538,"Both")) | I7: =IF(K7=J7,"",COUNTIFS('Raw Log'!$F$5:$F$1538,A7,'Raw Log'!$B$5:$B$1538,"Diaper",'Raw Log'!$D$5:$D$1538,"Poop")+COUNTIFS('Raw Log'!$F$5:$F$1538,A7,'Raw Log'!$B$5:$B$1538,"Diaper",'Raw Log'!$D$5:$D$1538,"Both")) | J7: =COUNTIFS('Raw Log'!$F$5:$F$1538,A7,'Raw Log'!$B$5:$B$1538,"Diaper") -> 5 | K7: =J7-COUNTIFS('Raw Log'!$F$5:$F$1538,A7,'Raw Log'!$B$5:$B$1538,"Diaper",'Raw Log'!$D$5:$D$1538,"Pee")-COUNTIFS('Raw Log'!$F$5:$F$1538,A7,'Raw Log'!$B$5:$B$1538,"Diaper",'Raw Log'!$D$5:$D$1538,"Poop")-COUNTIFS('Raw Log'!$F$5:$F$1538,A7,'Raw Log'!$B$5:$B$1538,"Diaper",'Raw Log'!$D$5:$D$1538,"Both") -> 5 | L7: =COUNTIFS('Sleep Detail'!$A$5:$A$285,A7,'Sleep Detail'!$B$5:$B$285,"Nap") -> 1 | M7: =SUMIFS('Sleep Detail'!$E$5:$E$285,'Sleep Detail'!$A$5:$A$285,A7,'Sleep Detail'!$B$5:$B$285,"Nap") -> 1.35 | N7: =IF(COUNTIFS('Sleep Detail'!$A$5:$A$285,A7,'Sleep Detail'!$B$5:$B$285,"Night")=0,"",_xlfn.MINIFS('Sleep Detail'!$C$5:$C$285,'Sleep Detail'!$A$5:$A$285,A7,'Sleep Detail'!$B$5:$B$285,"Night")) -> 46251.012 | O7: =IF(COUNTIFS('Sleep Detail'!$A$5:$A$285,A7,'Sleep Detail'!$B$5:$B$285,"Night")=0,"",_xlfn.MAXIFS('Sleep Detail'!$D$5:$D$285,'Sleep Detail'!$A$5:$A$285,A7,'Sleep Detail'!$B$5:$B$285,"Night")) -> 46251.334 | P7: =IF(COUNTIFS('Sleep Detail'!$A$5:$A$285,A7,'Sleep Detail'!$B$5:$B$285,"Night")=0,"",SUMIFS('Sleep Detail'!$E$5:$E$285,'Sleep Detail'!$A$5:$A$285,A7,'Sleep Detail'!$B$5:$B$285,"Night")) -> 7.7333333 | Q7: =IF(P7="","",M7+P7) -> 9.0833333 | R7: =COUNTIFS('Raw Log'!$F$5:$F$1538,A7,'Raw Log'!$B$5:$B$1538,"Medicine") -> 4 | S7: =IF(N7="","",MOD(N7-0.5,1)*24) -> 12.283333 | T7: =IF(O7="","",MOD(O7,1)) -> 0.33402778
A8: 46251 | B8: =A8-WEEKDAY(A8,3) -> 46251 | C8: Yes | D8: =COUNTIFS('Raw Log'!$F$5:$F$1538,A8,'Raw Log'!$B$5:$B$1538,"Feed") -> 6 | E8: =COUNTIFS('Raw Log'!$F$5:$F$1538,A8,'Raw Log'!$B$5:$B$1538,"Feed",'Raw Log'!$C$5:$C$1538,">0") -> 0 | F8: =IF(E8=0,"",SUMIFS('Raw Log'!$C$5:$C$1538,'Raw Log'!$F$5:$F$1538,A8,'Raw Log'!$B$5:$B$1538,"Feed")) | G8: =IF(E8=0,"",F8/E8) | H8: =IF(K8=J8,"",COUNTIFS('Raw Log'!$F$5:$F$1538,A8,'Raw Log'!$B$5:$B$1538,"Diaper",'Raw Log'!$D$5:$D$1538,"Pee")+COUNTIFS('Raw Log'!$F$5:$F$1538,A8,'Raw Log'!$B$5:$B$1538,"Diaper",'Raw Log'!$D$5:$D$1538,"Both")) | I8: =IF(K8=J8,"",COUNTIFS('Raw Log'!$F$5:$F$1538,A8,'Raw Log'!$B$5:$B$1538,"Diaper",'Raw Log'!$D$5:$D$1538,"Poop")+COUNTIFS('Raw Log'!$F$5:$F$1538,A8,'Raw Log'!$B$5:$B$1538,"Diaper",'Raw Log'!$D$5:$D$1538,"Both")) | J8: =COUNTIFS('Raw Log'!$F$5:$F$1538,A8,'Raw Log'!$B$5:$B$1538,"Diaper") -> 6 | K8: =J8-COUNTIFS('Raw Log'!$F$5:$F$1538,A8,'Raw Log'!$B$5:$B$1538,"Diaper",'Raw Log'!$D$5:$D$1538,"Pee")-COUNTIFS('Raw Log'!$F$5:$F$1538,A8,'Raw Log'!$B$5:$B$1538,"Diaper",'Raw Log'!$D$5:$D$1538,"Poop")-COUNTIFS('Raw Log'!$F$5:$F$1538,A8,'Raw Log'!$B$5:$B$1538,"Diaper",'Raw Log'!$D$5:$D$1538,"Both") -> 6 | L8: =COUNTIFS('Sleep Detail'!$A$5:$A$285,A8,'Sleep Detail'!$B$5:$B$285,"Nap") -> 5 | M8: =SUMIFS('Sleep Detail'!$E$5:$E$285,'Sleep Detail'!$A$5:$A$285,A8,'Sleep Detail'!$B$5:$B$285,"Nap") -> 1.8333333 | N8: =IF(COUNTIFS('Sleep Detail'!$A$5:$A$285,A8,'Sleep Detail'!$B$5:$B$285,"Night")=0,"",_xlfn.MINIFS('Sleep Detail'!$C$5:$C$285,'Sleep Detail'!$A$5:$A$285,A8,'Sleep Detail'!$B$5:$B$285,"Night")) -> 46252.007 | O8: =IF(COUNTIFS('Sleep Detail'!$A$5:$A$285,A8,'Sleep Detail'!$B$5:$B$285,"Night")=0,"",_xlfn.MAXIFS('Sleep Detail'!$D$5:$D$285,'Sleep Detail'!$A$5:$A$285,A8,'Sleep Detail'!$B$5:$B$285,"Night")) -> 46252.295 | P8: =IF(COUNTIFS('Sleep Detail'!$A$5:$A$285,A8,'Sleep Detail'!$B$5:$B$285,"Night")=0,"",SUMIFS('Sleep Detail'!$E$5:$E$285,'Sleep Detail'!$A$5:$A$285,A8,'Sleep Detail'!$B$5:$B$285,"Night")) -> 6.9166667 | Q8: =IF(P8="","",M8+P8) -> 8.75 | R8: =COUNTIFS('Raw Log'!$F$5:$F$1538,A8,'Raw Log'!$B$5:$B$1538,"Medicine") -> 3 | S8: =IF(N8="","",MOD(N8-0.5,1)*24) -> 12.166667 | T8: =IF(O8="","",MOD(O8,1)) -> 0.29513889
A9: 46252 | B9: =A9-WEEKDAY(A9,3) -> 46251 | C9: Yes | D9: =COUNTIFS('Raw Log'!$F$5:$F$1538,A9,'Raw Log'!$B$5:$B$1538,"Feed") -> 6 | E9: =COUNTIFS('Raw Log'!$F$5:$F$1538,A9,'Raw Log'!$B$5:$B$1538,"Feed",'Raw Log'!$C$5:$C$1538,">0") -> 0 | F9: =IF(E9=0,"",SUMIFS('Raw Log'!$C$5:$C$1538,'Raw Log'!$F$5:$F$1538,A9,'Raw Log'!$B$5:$B$1538,"Feed")) | G9: =IF(E9=0,"",F9/E9) | H9: =IF(K9=J9,"",COUNTIFS('Raw Log'!$F$5:$F$1538,A9,'Raw Log'!$B$5:$B$1538,"Diaper",'Raw Log'!$D$5:$D$1538,"Pee")+COUNTIFS('Raw Log'!$F$5:$F$1538,A9,'Raw Log'!$B$5:$B$1538,"Diaper",'Raw Log'!$D$5:$D$1538,"Both")) | I9: =IF(K9=J9,"",COUNTIFS('Raw Log'!$F$5:$F$1538,A9,'Raw Log'!$B$5:$B$1538,"Diaper",'Raw Log'!$D$5:$D$1538,"Poop")+COUNTIFS('Raw Log'!$F$5:$F$1538,A9,'Raw Log'!$B$5:$B$1538,"Diaper",'Raw Log'!$D$5:$D$1538,"Both")) | J9: =COUNTIFS('Raw Log'!$F$5:$F$1538,A9,'Raw Log'!$B$5:$B$1538,"Diaper") -> 7 | K9: =J9-COUNTIFS('Raw Log'!$F$5:$F$1538,A9,'Raw Log'!$B$5:$B$1538,"Diaper",'Raw Log'!$D$5:$D$1538,"Pee")-COUNTIFS('Raw Log'!$F$5:$F$1538,A9,'Raw Log'!$B$5:$B$1538,"Diaper",'Raw Log'!$D$5:$D$1538,"Poop")-COUNTIFS('Raw Log'!$F$5:$F$1538,A9,'Raw Log'!$B$5:$B$1538,"Diaper",'Raw Log'!$D$5:$D$1538,"Both") -> 7 | L9: =COUNTIFS('Sleep Detail'!$A$5:$A$285,A9,'Sleep Detail'!$B$5:$B$285,"Nap") -> 4 | M9: =SUMIFS('Sleep Detail'!$E$5:$E$285,'Sleep Detail'!$A$5:$A$285,A9,'Sleep Detail'!$B$5:$B$285,"Nap") -> 2.9833333 | N9: =IF(COUNTIFS('Sleep Detail'!$A$5:$A$285,A9,'Sleep Detail'!$B$5:$B$285,"Night")=0,"",_xlfn.MINIFS('Sleep Detail'!$C$5:$C$285,'Sleep Detail'!$A$5:$A$285,A9,'Sleep Detail'!$B$5:$B$285,"Night")) | O9: =IF(COUNTIFS('Sleep Detail'!$A$5:$A$285,A9,'Sleep Detail'!$B$5:$B$285,"Night")=0,"",_xlfn.MAXIFS('Sleep Detail'!$D$5:$D$285,'Sleep Detail'!$A$5:$A$285,A9,'Sleep Detail'!$B$5:$B$285,"Night")) | P9: =IF(COUNTIFS('Sleep Detail'!$A$5:$A$285,A9,'Sleep Detail'!$B$5:$B$285,"Night")=0,"",SUMIFS('Sleep Detail'!$E$5:$E$285,'Sleep Detail'!$A$5:$A$285,A9,'Sleep Detail'!$B$5:$B$285,"Night")) | Q9: =IF(P9="","",M9+P9) | R9: =COUNTIFS('Raw Log'!$F$5:$F$1538,A9,'Raw Log'!$B$5:$B$1538,"Medicine") -> 3 | S9: =IF(N9="","",MOD(N9-0.5,1)*24) | T9: =IF(O9="","",MOD(O9,1))
A10: 46253 | B10: =A10-WEEKDAY(A10,3) -> 46251 | C10: Yes | D10: =COUNTIFS('Raw Log'!$F$5:$F$1538,A10,'Raw Log'!$B$5:$B$1538,"Feed") -> 6 | E10: =COUNTIFS('Raw Log'!$F$5:$F$1538,A10,'Raw Log'!$B$5:$B$1538,"Feed",'Raw Log'!$C$5:$C$1538,">0") -> 0 | F10: =IF(E10=0,"",SUMIFS('Raw Log'!$C$5:$C$1538,'Raw Log'!$F$5:$F$1538,A10,'Raw Log'!$B$5:$B$1538,"Feed")) | G10: =IF(E10=0,"",F10/E10) | H10: =IF(K10=J10,"",COUNTIFS('Raw Log'!$F$5:$F$1538,A10,'Raw Log'!$B$5:$B$1538,"Diaper",'Raw Log'!$D$5:$D$1538,"Pee")+COUNTIFS('Raw Log'!$F$5:$F$1538,A10,'Raw Log'!$B$5:$B$1538,"Diaper",'Raw Log'!$D$5:$D$1538,"Both")) | I10: =IF(K10=J10,"",COUNTIFS('Raw Log'!$F$5:$F$1538,A10,'Raw Log'!$B$5:$B$1538,"Diaper",'Raw Log'!$D$5:$D$1538,"Poop")+COUNTIFS('Raw Log'!$F$5:$F$1538,A10,'Raw Log'!$B$5:$B$1538,"Diaper",'Raw Log'!$D$5:$D$1538,"Both")) | J10: =COUNTIFS('Raw Log'!$F$5:$F$1538,A10,'Raw Log'!$B$5:$B$1538,"Diaper") -> 7 | K10: =J10-COUNTIFS('Raw Log'!$F$5:$F$1538,A10,'Raw Log'!$B$5:$B$1538,"Diaper",'Raw Log'!$D$5:$D$1538,"Pee")-COUNTIFS('Raw Log'!$F$5:$F$1538,A10,'Raw Log'!$B$5:$B$1538,"Diaper",'Raw Log'!$D$5:$D$1538,"Poop")-COUNTIFS('Raw Log'!$F$5:$F$1538,A10,'Raw Log'!$B$5:$B$1538,"Diaper",'Raw Log'!$D$5:$D$1538,"Both") -> 7 | L10: =COUNTIFS('Sleep Detail'!$A$5:$A$285,A10,'Sleep Detail'!$B$5:$B$285,"Nap") -> 4 | M10: =SUMIFS('Sleep Detail'!$E$5:$E$285,'Sleep Detail'!$A$5:$A$285,A10,'Sleep Detail'!$B$5:$B$285,"Nap") -> 2.0666667 | N10: =IF(COUNTIFS('Sleep Detail'!$A$5:$A$285,A10,'Sleep Detail'!$B$5:$B$285,"Night")=0,"",_xlfn.MINIFS('Sleep Detail'!$C$5:$C$285,'Sleep Detail'!$A$5:$A$285,A10,'Sleep Detail'!$B$5:$B$285,"Night")) -> 46254.019 | O10: =IF(COUNTIFS('Sleep Detail'!$A$5:$A$285,A10,'Sleep Detail'!$B$5:$B$285,"Night")=0,"",_xlfn.MAXIFS('Sleep Detail'!$D$5:$D$285,'Sleep Detail'!$A$5:$A$285,A10,'Sleep Detail'!$B$5:$B$285,"Night")) -> 46254.319 | P10: =IF(COUNTIFS('Sleep Detail'!$A$5:$A$285,A10,'Sleep Detail'!$B$5:$B$285,"Night")=0,"",SUMIFS('Sleep Detail'!$E$5:$E$285,'Sleep Detail'!$A$5:$A$285,A10,'Sleep Detail'!$B$5:$B$285,"Night")) -> 7.2 | Q10: =IF(P10="","",M10+P10) -> 9.2666667 | R10: =COUNTIFS('Raw Log'!$F$5:$F$1538,A10,'Raw Log'!$B$5:$B$1538,"Medicine") -> 3 | S10: =IF(N10="","",MOD(N10-0.5,1)*24) -> 12.466667 | T10: =IF(O10="","",MOD(O10,1)) -> 0.31944444
A11: 46254 | B11: =A11-WEEKDAY(A11,3) -> 46251 | C11: Yes | D11: =COUNTIFS('Raw Log'!$F$5:$F$1538,A11,'Raw Log'!$B$5:$B$1538,"Feed") -> 6 | E11: =COUNTIFS('Raw Log'!$F$5:$F$1538,A11,'Raw Log'!$B$5:$B$1538,"Feed",'Raw Log'!$C$5:$C$1538,">0") -> 0 | F11: =IF(E11=0,"",SUMIFS('Raw Log'!$C$5:$C$1538,'Raw Log'!$F$5:$F$1538,A11,'Raw Log'!$B$5:$B$1538,"Feed")) | G11: =IF(E11=0,"",F11/E11) | H11: =IF(K11=J11,"",COUNTIFS('Raw Log'!$F$5:$F$1538,A11,'Raw Log'!$B$5:$B$1538,"Diaper",'Raw Log'!$D$5:$D$1538,"Pee")+COUNTIFS('Raw Log'!$F$5:$F$1538,A11,'Raw Log'!$B$5:$B$1538,"Diaper",'Raw Log'!$D$5:$D$1538,"Both")) | I11: =IF(K11=J11,"",COUNTIFS('Raw Log'!$F$5:$F$1538,A11,'Raw Log'!$B$5:$B$1538,"Diaper",'Raw Log'!$D$5:$D$1538,"Poop")+COUNTIFS('Raw Log'!$F$5:$F$1538,A11,'Raw Log'!$B$5:$B$1538,"Diaper",'Raw Log'!$D$5:$D$1538,"Both")) | J11: =COUNTIFS('Raw Log'!$F$5:$F$1538,A11,'Raw Log'!$B$5:$B$1538,"Diaper") -> 5 | K11: =J11-COUNTIFS('Raw Log'!$F$5:$F$1538,A11,'Raw Log'!$B$5:$B$1538,"Diaper",'Raw Log'!$D$5:$D$1538,"Pee")-COUNTIFS('Raw Log'!$F$5:$F$1538,A11,'Raw Log'!$B$5:$B$1538,"Diaper",'Raw Log'!$D$5:$D$1538,"Poop")-COUNTIFS('Raw Log'!$F$5:$F$1538,A11,'Raw Log'!$B$5:$B$1538,"Diaper",'Raw Log'!$D$5:$D$1538,"Both") -> 5 | L11: =COUNTIFS('Sleep Detail'!$A$5:$A$285,A11,'Sleep Detail'!$B$5:$B$285,"Nap") -> 2 | M11: =SUMIFS('Sleep Detail'!$E$5:$E$285,'Sleep Detail'!$A$5:$A$285,A11,'Sleep Detail'!$B$5:$B$285,"Nap") -> 1.1666667 | N11: =IF(COUNTIFS('Sleep Detail'!$A$5:$A$285,A11,'Sleep Detail'!$B$5:$B$285,"Night")=0,"",_xlfn.MINIFS('Sleep Detail'!$C$5:$C$285,'Sleep Detail'!$A$5:$A$285,A11,'Sleep Detail'!$B$5:$B$285,"Night")) -> 46255.031 | O11: =IF(COUNTIFS('Sleep Detail'!$A$5:$A$285,A11,'Sleep Detail'!$B$5:$B$285,"Night")=0,"",_xlfn.MAXIFS('Sleep Detail'!$D$5:$D$285,'Sleep Detail'!$A$5:$A$285,A11,'Sleep Detail'!$B$5:$B$285,"Night")) -> 46255.365 | P11: =IF(COUNTIFS('Sleep Detail'!$A$5:$A$285,A11,'Sleep Detail'!$B$5:$B$285,"Night")=0,"",SUMIFS('Sleep Detail'!$E$5:$E$285,'Sleep Detail'!$A$5:$A$285,A11,'Sleep Detail'!$B$5:$B$285,"Night")) -> 8.0166667 | Q11: =IF(P11="","",M11+P11) -> 9.1833333 | R11: =COUNTIFS('Raw Log'!$F$5:$F$1538,A11,'Raw Log'!$B$5:$B$1538,"Medicine") -> 3 | S11: =IF(N11="","",MOD(N11-0.5,1)*24) -> 12.733333 | T11: =IF(O11="","",MOD(O11,1)) -> 0.36458333
A12: 46255 | B12: =A12-WEEKDAY(A12,3) -> 46251 | C12: Yes | D12: =COUNTIFS('Raw Log'!$F$5:$F$1538,A12,'Raw Log'!$B$5:$B$1538,"Feed") -> 5 | E12: =COUNTIFS('Raw Log'!$F$5:$F$1538,A12,'Raw Log'!$B$5:$B$1538,"Feed",'Raw Log'!$C$5:$C$1538,">0") -> 0 | F12: =IF(E12=0,"",SUMIFS('Raw Log'!$C$5:$C$1538,'Raw Log'!$F$5:$F$1538,A12,'Raw Log'!$B$5:$B$1538,"Feed")) | G12: =IF(E12=0,"",F12/E12) | H12: =IF(K12=J12,"",COUNTIFS('Raw Log'!$F$5:$F$1538,A12,'Raw Log'!$B$5:$B$1538,"Diaper",'Raw Log'!$D$5:$D$1538,"Pee")+COUNTIFS('Raw Log'!$F$5:$F$1538,A12,'Raw Log'!$B$5:$B$1538,"Diaper",'Raw Log'!$D$5:$D$1538,"Both")) | I12: =IF(K12=J12,"",COUNTIFS('Raw Log'!$F$5:$F$1538,A12,'Raw Log'!$B$5:$B$1538,"Diaper",'Raw Log'!$D$5:$D$1538,"Poop")+COUNTIFS('Raw Log'!$F$5:$F$1538,A12,'Raw Log'!$B$5:$B$1538,"Diaper",'Raw Log'!$D$5:$D$1538,"Both")) | J12: =COUNTIFS('Raw Log'!$F$5:$F$1538,A12,'Raw Log'!$B$5:$B$1538,"Diaper") -> 6 | K12: =J12-COUNTIFS('Raw Log'!$F$5:$F$1538,A12,'Raw Log'!$B$5:$B$1538,"Diaper",'Raw Log'!$D$5:$D$1538,"Pee")-COUNTIFS('Raw Log'!$F$5:$F$1538,A12,'Raw Log'!$B$5:$B$1538,"Diaper",'Raw Log'!$D$5:$D$1538,"Poop")-COUNTIFS('Raw Log'!$F$5:$F$1538,A12,'Raw Log'!$B$5:$B$1538,"Diaper",'Raw Log'!$D$5:$D$1538,"Both") -> 6 | L12: =COUNTIFS('Sleep Detail'!$A$5:$A$285,A12,'Sleep Detail'!$B$5:$B$285,"Nap") -> 2 | M12: =SUMIFS('Sleep Detail'!$E$5:$E$285,'Sleep Detail'!$A$5:$A$285,A12,'Sleep Detail'!$B$5:$B$285,"Nap") -> 2.8 | N12: =IF(COUNTIFS('Sleep Detail'!$A$5:$A$285,A12,'Sleep Detail'!$B$5:$B$285,"Night")=0,"",_xlfn.MINIFS('Sleep Detail'!$C$5:$C$285,'Sleep Detail'!$A$5:$A$285,A12,'Sleep Detail'!$B$5:$B$285,"Night")) -> 46256.069 | O12: =IF(COUNTIFS('Sleep Detail'!$A$5:$A$285,A12,'Sleep Detail'!$B$5:$B$285,"Night")=0,"",_xlfn.MAXIFS('Sleep Detail'!$D$5:$D$285,'Sleep Detail'!$A$5:$A$285,A12,'Sleep Detail'!$B$5:$B$285,"Night")) -> 46256.334 | P12: =IF(COUNTIFS('Sleep Detail'!$A$5:$A$285,A12,'Sleep Detail'!$B$5:$B$285,"Night")=0,"",SUMIFS('Sleep Detail'!$E$5:$E$285,'Sleep Detail'!$A$5:$A$285,A12,'Sleep Detail'!$B$5:$B$285,"Night")) -> 6.35 | Q12: =IF(P12="","",M12+P12) -> 9.15 | R12: =COUNTIFS('Raw Log'!$F$5:$F$1538,A12,'Raw Log'!$B$5:$B$1538,"Medicine") -> 3 | S12: =IF(N12="","",MOD(N12-0.5,1)*24) -> 13.666667 | T12: =IF(O12="","",MOD(O12,1)) -> 0.33402778
A13: 46256 | B13: =A13-WEEKDAY(A13,3) -> 46251 | C13: Yes | D13: =COUNTIFS('Raw Log'!$F$5:$F$1538,A13,'Raw Log'!$B$5:$B$1538,"Feed") -> 6 | E13: =COUNTIFS('Raw Log'!$F$5:$F$1538,A13,'Raw Log'!$B$5:$B$1538,"Feed",'Raw Log'!$C$5:$C$1538,">0") -> 0 | F13: =IF(E13=0,"",SUMIFS('Raw Log'!$C$5:$C$1538,'Raw Log'!$F$5:$F$1538,A13,'Raw Log'!$B$5:$B$1538,"Feed")) | G13: =IF(E13=0,"",F13/E13) | H13: =IF(K13=J13,"",COUNTIFS('Raw Log'!$F$5:$F$1538,A13,'Raw Log'!$B$5:$B$1538,"Diaper",'Raw Log'!$D$5:$D$1538,"Pee")+COUNTIFS('Raw Log'!$F$5:$F$1538,A13,'Raw Log'!$B$5:$B$1538,"Diaper",'Raw Log'!$D$5:$D$1538,"Both")) | I13: =IF(K13=J13,"",COUNTIFS('Raw Log'!$F$5:$F$1538,A13,'Raw Log'!$B$5:$B$1538,"Diaper",'Raw Log'!$D$5:$D$1538,"Poop")+COUNTIFS('Raw Log'!$F$5:$F$1538,A13,'Raw Log'!$B$5:$B$1538,"Diaper",'Raw Log'!$D$5:$D$1538,"Both")) | J13: =COUNTIFS('Raw Log'!$F$5:$F$1538,A13,'Raw Log'!$B$5:$B$1538,"Diaper") -> 5 | K13: =J13-COUNTIFS('Raw Log'!$F$5:$F$1538,A13,'Raw Log'!$B$5:$B$1538,"Diaper",'Raw Log'!$D$5:$D$1538,"Pee")-COUNTIFS('Raw Log'!$F$5:$F$1538,A13,'Raw Log'!$B$5:$B$1538,"Diaper",'Raw Log'!$D$5:$D$1538,"Poop")-COUNTIFS('Raw Log'!$F$5:$F$1538,A13,'Raw Log'!$B$5:$B$1538,"Diaper",'Raw Log'!$D$5:$D$1538,"Both") -> 5 | L13: =COUNTIFS('Sleep Detail'!$A$5:$A$285,A13,'Sleep Detail'!$B$5:$B$285,"Nap") -> 6 | M13: =SUMIFS('Sleep Detail'!$E$5:$E$285,'Sleep Detail'!$A$5:$A$285,A13,'Sleep Detail'!$B$5:$B$285,"Nap") -> 5 | N13: =IF(COUNTIFS('Sleep Detail'!$A$5:$A$285,A13,'Sleep Detail'!$B$5:$B$285,"Night")=0,"",_xlfn.MINIFS('Sleep Detail'!$C$5:$C$285,'Sleep Detail'!$A$5:$A$285,A13,'Sleep Detail'!$B$5:$B$285,"Night")) | O13: =IF(COUNTIFS('Sleep Detail'!$A$5:$A$285,A13,'Sleep Detail'!$B$5:$B$285,"Night")=0,"",_xlfn.MAXIFS('Sleep Detail'!$D$5:$D$285,'Sleep Detail'!$A$5:$A$285,A13,'Sleep Detail'!$B$5:$B$285,"Night")) | P13: =IF(COUNTIFS('Sleep Detail'!$A$5:$A$285,A13,'Sleep Detail'!$B$5:$B$285,"Night")=0,"",SUMIFS('Sleep Detail'!$E$5:$E$285,'Sleep Detail'!$A$5:$A$285,A13,'Sleep Detail'!$B$5:$B$285,"Night")) | Q13: =IF(P13="","",M13+P13) | R13: =COUNTIFS('Raw Log'!$F$5:$F$1538,A13,'Raw Log'!$B$5:$B$1538,"Medicine") -> 3 | S13: =IF(N13="","",MOD(N13-0.5,1)*24) | T13: =IF(O13="","",MOD(O13,1))
A14: 46257 | B14: =A14-WEEKDAY(A14,3) -> 46251 | C14: Yes | D14: =COUNTIFS('Raw Log'!$F$5:$F$1538,A14,'Raw Log'!$B$5:$B$1538,"Feed") -> 6 | E14: =COUNTIFS('Raw Log'!$F$5:$F$1538,A14,'Raw Log'!$B$5:$B$1538,"Feed",'Raw Log'!$C$5:$C$1538,">0") -> 0 | F14: =IF(E14=0,"",SUMIFS('Raw Log'!$C$5:$C$1538,'Raw Log'!$F$5:$F$1538,A14,'Raw Log'!$B$5:$B$1538,"Feed")) | G14: =IF(E14=0,"",F14/E14) | H14: =IF(K14=J14,"",COUNTIFS('Raw Log'!$F$5:$F$1538,A14,'Raw Log'!$B$5:$B$1538,"Diaper",'Raw Log'!$D$5:$D$1538,"Pee")+COUNTIFS('Raw Log'!$F$5:$F$1538,A14,'Raw Log'!$B$5:$B$1538,"Diaper",'Raw Log'!$D$5:$D$1538,"Both")) | I14: =IF(K14=J14,"",COUNTIFS('Raw Log'!$F$5:$F$1538,A14,'Raw Log'!$B$5:$B$1538,"Diaper",'Raw Log'!$D$5:$D$1538,"Poop")+COUNTIFS('Raw Log'!$F$5:$F$1538,A14,'Raw Log'!$B$5:$B$1538,"Diaper",'Raw Log'!$D$5:$D$1538,"Both")) | J14: =COUNTIFS('Raw Log'!$F$5:$F$1538,A14,'Raw Log'!$B$5:$B$1538,"Diaper") -> 6 | K14: =J14-COUNTIFS('Raw Log'!$F$5:$F$1538,A14,'Raw Log'!$B$5:$B$1538,"Diaper",'Raw Log'!$D$5:$D$1538,"Pee")-COUNTIFS('Raw Log'!$F$5:$F$1538,A14,'Raw Log'!$B$5:$B$1538,"Diaper",'Raw Log'!$D$5:$D$1538,"Poop")-COUNTIFS('Raw Log'!$F$5:$F$1538,A14,'Raw Log'!$B$5:$B$1538,"Diaper",'Raw Log'!$D$5:$D$1538,"Both") -> 6 | L14: =COUNTIFS('Sleep Detail'!$A$5:$A$285,A14,'Sleep Detail'!$B$5:$B$285,"Nap") -> 2 | M14: =SUMIFS('Sleep Detail'!$E$5:$E$285,'Sleep Detail'!$A$5:$A$285,A14,'Sleep Detail'!$B$5:$B$285,"Nap") -> 2.25 | N14: =IF(COUNTIFS('Sleep Detail'!$A$5:$A$285,A14,'Sleep Detail'!$B$5:$B$285,"Night")=0,"",_xlfn.MINIFS('Sleep Detail'!$C$5:$C$285,'Sleep Detail'!$A$5:$A$285,A14,'Sleep Detail'!$B$5:$B$285,"Night")) -> 46258.026 | O14: =IF(COUNTIFS('Sleep Detail'!$A$5:$A$285,A14,'Sleep Detail'!$B$5:$B$285,"Night")=0,"",_xlfn.MAXIFS('Sleep Detail'!$D$5:$D$285,'Sleep Detail'!$A$5:$A$285,A14,'Sleep Detail'!$B$5:$B$285,"Night")) -> 46258.233 | P14: =IF(COUNTIFS('Sleep Detail'!$A$5:$A$285,A14,'Sleep Detail'!$B$5:$B$285,"Night")=0,"",SUMIFS('Sleep Detail'!$E$5:$E$285,'Sleep Detail'!$A$5:$A$285,A14,'Sleep Detail'!$B$5:$B$285,"Night")) -> 4.95 | Q14: =IF(P14="","",M14+P14) -> 7.2 | R14: =COUNTIFS('Raw Log'!$F$5:$F$1538,A14,'Raw Log'!$B$5:$B$1538,"Medicine") -> 3 | S14: =IF(N14="","",MOD(N14-0.5,1)*24) -> 12.633333 | T14: =IF(O14="","",MOD(O14,1)) -> 0.23263889
A15: 46258 | B15: =A15-WEEKDAY(A15,3) -> 46258 | C15: Yes | D15: =COUNTIFS('Raw Log'!$F$5:$F$1538,A15,'Raw Log'!$B$5:$B$1538,"Feed") -> 6 | E15: =COUNTIFS('Raw Log'!$F$5:$F$1538,A15,'Raw Log'!$B$5:$B$1538,"Feed",'Raw Log'!$C$5:$C$1538,">0") -> 1 | F15: =IF(E15=0,"",SUMIFS('Raw Log'!$C$5:$C$1538,'Raw Log'!$F$5:$F$1538,A15,'Raw Log'!$B$5:$B$1538,"Feed")) -> 4 | G15: =IF(E15=0,"",F15/E15) -> 4 | H15: =IF(K15=J15,"",COUNTIFS('Raw Log'!$F$5:$F$1538,A15,'Raw Log'!$B$5:$B$1538,"Diaper",'Raw Log'!$D$5:$D$1538,"Pee")+COUNTIFS('Raw Log'!$F$5:$F$1538,A15,'Raw Log'!$B$5:$B$1538,"Diaper",'Raw Log'!$D$5:$D$1538,"Both")) -> 1 | I15: =IF(K15=J15,"",COUNTIFS('Raw Log'!$F$5:$F$1538,A15,'Raw Log'!$B$5:$B$1538,"Diaper",'Raw Log'!$D$5:$D$1538,"Poop")+COUNTIFS('Raw Log'!$F$5:$F$1538,A15,'Raw Log'!$B$5:$B$1538,"Diaper",'Raw Log'!$D$5:$D$1538,"Both")) -> 0 | J15: =COUNTIFS('Raw Log'!$F$5:$F$1538,A15,'Raw Log'!$B$5:$B$1538,"Diaper") -> 6 | K15: =J15-COUNTIFS('Raw Log'!$F$5:$F$1538,A15,'Raw Log'!$B$5:$B$1538,"Diaper",'Raw Log'!$D$5:$D$1538,"Pee")-COUNTIFS('Raw Log'!$F$5:$F$1538,A15,'Raw Log'!$B$5:$B$1538,"Diaper",'Raw Log'!$D$5:$D$1538,"Poop")-COUNTIFS('Raw Log'!$F$5:$F$1538,A15,'Raw Log'!$B$5:$B$1538,"Diaper",'Raw Log'!$D$5:$D$1538,"Both") -> 5 | L15: =COUNTIFS('Sleep Detail'!$A$5:$A$285,A15,'Sleep Detail'!$B$5:$B$285,"Nap") -> 5 | M15: =SUMIFS('Sleep Detail'!$E$5:$E$285,'Sleep Detail'!$A$5:$A$285,A15,'Sleep Detail'!$B$5:$B$285,"Nap") -> 4.0833333 | N15: =IF(COUNTIFS('Sleep Detail'!$A$5:$A$285,A15,'Sleep Detail'!$B$5:$B$285,"Night")=0,"",_xlfn.MINIFS('Sleep Detail'!$C$5:$C$285,'Sleep Detail'!$A$5:$A$285,A15,'Sleep Detail'!$B$5:$B$285,"Night")) -> 46259.021 | O15: =IF(COUNTIFS('Sleep Detail'!$A$5:$A$285,A15,'Sleep Detail'!$B$5:$B$285,"Night")=0,"",_xlfn.MAXIFS('Sleep Detail'!$D$5:$D$285,'Sleep Detail'!$A$5:$A$285,A15,'Sleep Detail'!$B$5:$B$285,"Night")) -> 46259.293 | P15: =IF(COUNTIFS('Sleep Detail'!$A$5:$A$285,A15,'Sleep Detail'!$B$5:$B$285,"Night")=0,"",SUMIFS('Sleep Detail'!$E$5:$E$285,'Sleep Detail'!$A$5:$A$285,A15,'Sleep Detail'!$B$5:$B$285,"Night")) -> 6.5333333 | Q15: =IF(P15="","",M15+P15) -> 10.616667 | R15: =COUNTIFS('Raw Log'!$F$5:$F$1538,A15,'Raw Log'!$B$5:$B$1538,"Medicine") -> 2 | S15: =IF(N15="","",MOD(N15-0.5,1)*24) -> 12.5 | T15: =IF(O15="","",MOD(O15,1)) -> 0.29305556
A16: 46259 | B16: =A16-WEEKDAY(A16,3) -> 46258 | C16: Yes | D16: =COUNTIFS('Raw Log'!$F$5:$F$1538,A16,'Raw Log'!$B$5:$B$1538,"Feed") -> 5 | E16: =COUNTIFS('Raw Log'!$F$5:$F$1538,A16,'Raw Log'!$B$5:$B$1538,"Feed",'Raw Log'!$C$5:$C$1538,">0") -> 4 | F16: =IF(E16=0,"",SUMIFS('Raw Log'!$C$5:$C$1538,'Raw Log'!$F$5:$F$1538,A16,'Raw Log'!$B$5:$B$1538,"Feed")) -> 16 | G16: =IF(E16=0,"",F16/E16) -> 4 | H16: =IF(K16=J16,"",COUNTIFS('Raw Log'!$F$5:$F$1538,A16,'Raw Log'!$B$5:$B$1538,"Diaper",'Raw Log'!$D$5:$D$1538,"Pee")+COUNTIFS('Raw Log'!$F$5:$F$1538,A16,'Raw Log'!$B$5:$B$1538,"Diaper",'Raw Log'!$D$5:$D$1538,"Both")) -> 5 | I16: =IF(K16=J16,"",COUNTIFS('Raw Log'!$F$5:$F$1538,A16,'Raw Log'!$B$5:$B$1538,"Diaper",'Raw Log'!$D$5:$D$1538,"Poop")+COUNTIFS('Raw Log'!$F$5:$F$1538,A16,'Raw Log'!$B$5:$B$1538,"Diaper",'Raw Log'!$D$5:$D$1538,"Both")) -> 0 | J16: =COUNTIFS('Raw Log'!$F$5:$F$1538,A16,'Raw Log'!$B$5:$B$1538,"Diaper") -> 6 | K16: =J16-COUNTIFS('Raw Log'!$F$5:$F$1538,A16,'Raw Log'!$B$5:$B$1538,"Diaper",'Raw Log'!$D$5:$D$1538,"Pee")-COUNTIFS('Raw Log'!$F$5:$F$1538,A16,'Raw Log'!$B$5:$B$1538,"Diaper",'Raw Log'!$D$5:$D$1538,"Poop")-COUNTIFS('Raw Log'!$F$5:$F$1538,A16,'Raw Log'!$B$5:$B$1538,"Diaper",'Raw Log'!$D$5:$D$1538,"Both") -> 1 | L16: =COUNTIFS('Sleep Detail'!$A$5:$A$285,A16,'Sleep Detail'!$B$5:$B$285,"Nap") -> 4 | M16: =SUMIFS('Sleep Detail'!$E$5:$E$285,'Sleep Detail'!$A$5:$A$285,A16,'Sleep Detail'!$B$5:$B$285,"Nap") -> 2 | N16: =IF(COUNTIFS('Sleep Detail'!$A$5:$A$285,A16,'Sleep Detail'!$B$5:$B$285,"Night")=0,"",_xlfn.MINIFS('Sleep Detail'!$C$5:$C$285,'Sleep Detail'!$A$5:$A$285,A16,'Sleep Detail'!$B$5:$B$285,"Night")) -> 46260.002 | O16: =IF(COUNTIFS('Sleep Detail'!$A$5:$A$285,A16,'Sleep Detail'!$B$5:$B$285,"Night")=0,"",_xlfn.MAXIFS('Sleep Detail'!$D$5:$D$285,'Sleep Detail'!$A$5:$A$285,A16,'Sleep Detail'!$B$5:$B$285,"Night")) -> 46260.252 | P16: =IF(COUNTIFS('Sleep Detail'!$A$5:$A$285,A16,'Sleep Detail'!$B$5:$B$285,"Night")=0,"",SUMIFS('Sleep Detail'!$E$5:$E$285,'Sleep Detail'!$A$5:$A$285,A16,'Sleep Detail'!$B$5:$B$285,"Night")) -> 6 | Q16: =IF(P16="","",M16+P16) -> 8 | R16: =COUNTIFS('Raw Log'!$F$5:$F$1538,A16,'Raw Log'!$B$5:$B$1538,"Medicine") -> 3 | S16: =IF(N16="","",MOD(N16-0.5,1)*24) -> 12.05 | T16: =IF(O16="","",MOD(O16,1)) -> 0.25208333
... A70: 46313 | B70: =A70-WEEKDAY(A70,3) -> 46307 | C70: No | D70: =COUNTIFS('Raw Log'!$F$5:$F$1538,A70,'Raw Log'!$B$5:$B$1538,"Feed") -> 3 | E70: =COUNTIFS('Raw Log'!$F$5:$F$1538,A70,'Raw Log'!$B$5:$B$1538,"Feed",'Raw Log'!$C$5:$C$1538,">0") -> 3 | F70: =IF(E70=0,"",SUMIFS('Raw Log'!$C$5:$C$1538,'Raw Log'!$F$5:$F$1538,A70,'Raw Log'!$B$5:$B$1538,"Feed")) -> 16 | G70: =IF(E70=0,"",F70/E70) -> 5.3333333 | H70: =IF(K70=J70,"",COUNTIFS('Raw Log'!$F$5:$F$1538,A70,'Raw Log'!$B$5:$B$1538,"Diaper",'Raw Log'!$D$5:$D$1538,"Pee")+COUNTIFS('Raw Log'!$F$5:$F$1538,A70,'Raw Log'!$B$5:$B$1538,"Diaper",'Raw Log'!$D$5:$D$1538,"Both")) -> 3 | I70: =IF(K70=J70,"",COUNTIFS('Raw Log'!$F$5:$F$1538,A70,'Raw Log'!$B$5:$B$1538,"Diaper",'Raw Log'!$D$5:$D$1538,"Poop")+COUNTIFS('Raw Log'!$F$5:$F$1538,A70,'Raw Log'!$B$5:$B$1538,"Diaper",'Raw Log'!$D$5:$D$1538,"Both")) -> 0 | J70: =COUNTIFS('Raw Log'!$F$5:$F$1538,A70,'Raw Log'!$B$5:$B$1538,"Diaper") -> 3 | K70: =J70-COUNTIFS('Raw Log'!$F$5:$F$1538,A70,'Raw Log'!$B$5:$B$1538,"Diaper",'Raw Log'!$D$5:$D$1538,"Pee")-COUNTIFS('Raw Log'!$F$5:$F$1538,A70,'Raw Log'!$B$5:$B$1538,"Diaper",'Raw Log'!$D$5:$D$1538,"Poop")-COUNTIFS('Raw Log'!$F$5:$F$1538,A70,'Raw Log'!$B$5:$B$1538,"Diaper",'Raw Log'!$D$5:$D$1538,"Both") -> 0 | L70: =COUNTIFS('Sleep Detail'!$A$5:$A$285,A70,'Sleep Detail'!$B$5:$B$285,"Nap") -> 3 | M70: =SUMIFS('Sleep Detail'!$E$5:$E$285,'Sleep Detail'!$A$5:$A$285,A70,'Sleep Detail'!$B$5:$B$285,"Nap") -> 2.2166667 | N70: =IF(COUNTIFS('Sleep Detail'!$A$5:$A$285,A70,'Sleep Detail'!$B$5:$B$285,"Night")=0,"",_xlfn.MINIFS('Sleep Detail'!$C$5:$C$285,'Sleep Detail'!$A$5:$A$285,A70,'Sleep Detail'!$B$5:$B$285,"Night")) | O70: =IF(COUNTIFS('Sleep Detail'!$A$5:$A$285,A70,'Sleep Detail'!$B$5:$B$285,"Night")=0,"",_xlfn.MAXIFS('Sleep Detail'!$D$5:$D$285,'Sleep Detail'!$A$5:$A$285,A70,'Sleep Detail'!$B$5:$B$285,"Night")) | P70: =IF(COUNTIFS('Sleep Detail'!$A$5:$A$285,A70,'Sleep Detail'!$B$5:$B$285,"Night")=0,"",SUMIFS('Sleep Detail'!$E$5:$E$285,'Sleep Detail'!$A$5:$A$285,A70,'Sleep Detail'!$B$5:$B$285,"Night")) | Q70: =IF(P70="","",M70+P70) | R70: =COUNTIFS('Raw Log'!$F$5:$F$1538,A70,'Raw Log'!$B$5:$B$1538,"Medicine") -> 2 | S70: =IF(N70="","",MOD(N70-0.5,1)*24) | T70: =IF(O70="","",MOD(O70,1))

Sheet Weekly Summary
A1: Weekly Summary
A2: Weeks run Monday to Sunday. Averages are per day and use only full days ("Include" = Yes on Daily Summary).
A4: Week of | B4: Days counted | C4: Feeds / day | D4: Oz / day | E4: Oz per feed | F4: Wet diapers / day | G4: Dirty diapers / day | H4: Naps / day | I4: Nap hrs / day | J4: Night sleep hrs | K4: Total sleep hrs / day | L4: Avg bedtime | M4: Avg wake-up | N4: Oz / day vs prior week | O4: Total sleep vs prior week (hrs)
A5: 46244 | B5: =COUNTIFS('Daily Summary'!$B$5:$B$70,A5,'Daily Summary'!$C$5:$C$70,"Yes") -> 2 | C5: =IFERROR(AVERAGEIFS('Daily Summary'!$D$5:$D$70,'Daily Summary'!$B$5:$B$70,$A5,'Daily Summary'!$C$5:$C$70,"Yes"),"") -> 6 | D5: =IFERROR(AVERAGEIFS('Daily Summary'!$F$5:$F$70,'Daily Summary'!$B$5:$B$70,$A5,'Daily Summary'!$C$5:$C$70,"Yes"),"") | E5: =IFERROR(SUMIFS('Daily Summary'!$F$5:$F$70,'Daily Summary'!$B$5:$B$70,$A5,'Daily Summary'!$C$5:$C$70,"Yes")/SUMIFS('Daily Summary'!$E$5:$E$70,'Daily Summary'!$B$5:$B$70,$A5,'Daily Summary'!$C$5:$C$70,"Yes"),"") | F5: =IFERROR(AVERAGEIFS('Daily Summary'!$H$5:$H$70,'Daily Summary'!$B$5:$B$70,$A5,'Daily Summary'!$C$5:$C$70,"Yes"),"") | G5: =IFERROR(AVERAGEIFS('Daily Summary'!$I$5:$I$70,'Daily Summary'!$B$5:$B$70,$A5,'Daily Summary'!$C$5:$C$70,"Yes"),"") | H5: =IFERROR(AVERAGEIFS('Daily Summary'!$L$5:$L$70,'Daily Summary'!$B$5:$B$70,$A5,'Daily Summary'!$C$5:$C$70,"Yes"),"") -> 3.5 | I5: =IFERROR(AVERAGEIFS('Daily Summary'!$M$5:$M$70,'Daily Summary'!$B$5:$B$70,$A5,'Daily Summary'!$C$5:$C$70,"Yes"),"") -> 3.025 | J5: =IFERROR(AVERAGEIFS('Daily Summary'!$P$5:$P$70,'Daily Summary'!$B$5:$B$70,$A5,'Daily Summary'!$C$5:$C$70,"Yes"),"") -> 6.1666667 | K5: =IFERROR(AVERAGEIFS('Daily Summary'!$Q$5:$Q$70,'Daily Summary'!$B$5:$B$70,$A5,'Daily Summary'!$C$5:$C$70,"Yes"),"") -> 9.1916667 | L5: =IFERROR(MOD(AVERAGEIFS('Daily Summary'!$S$5:$S$70,'Daily Summary'!$B$5:$B$70,$A5,'Daily Summary'!$C$5:$C$70,"Yes")/24+0.5,1),"") -> 0.037152778 | M5: =IFERROR(AVERAGEIFS('Daily Summary'!$T$5:$T$70,'Daily Summary'!$B$5:$B$70,$A5,'Daily Summary'!$C$5:$C$70,"Yes"),"") -> 0.29409722 | N5: ="" | O5: ="" | P5: Aug 10
A6: 46251 | B6: =COUNTIFS('Daily Summary'!$B$5:$B$70,A6,'Daily Summary'!$C$5:$C$70,"Yes") -> 7 | C6: =IFERROR(AVERAGEIFS('Daily Summary'!$D$5:$D$70,'Daily Summary'!$B$5:$B$70,$A6,'Daily Summary'!$C$5:$C$70,"Yes"),"") -> 5.8571429 | D6: =IFERROR(AVERAGEIFS('Daily Summary'!$F$5:$F$70,'Daily Summary'!$B$5:$B$70,$A6,'Daily Summary'!$C$5:$C$70,"Yes"),"") | E6: =IFERROR(SUMIFS('Daily Summary'!$F$5:$F$70,'Daily Summary'!$B$5:$B$70,$A6,'Daily Summary'!$C$5:$C$70,"Yes")/SUMIFS('Daily Summary'!$E$5:$E$70,'Daily Summary'!$B$5:$B$70,$A6,'Daily Summary'!$C$5:$C$70,"Yes"),"") | F6: =IFERROR(AVERAGEIFS('Daily Summary'!$H$5:$H$70,'Daily Summary'!$B$5:$B$70,$A6,'Daily Summary'!$C$5:$C$70,"Yes"),"") | G6: =IFERROR(AVERAGEIFS('Daily Summary'!$I$5:$I$70,'Daily Summary'!$B$5:$B$70,$A6,'Daily Summary'!$C$5:$C$70,"Yes"),"") | H6: =IFERROR(AVERAGEIFS('Daily Summary'!$L$5:$L$70,'Daily Summary'!$B$5:$B$70,$A6,'Daily Summary'!$C$5:$C$70,"Yes"),"") -> 3.5714286 | I6: =IFERROR(AVERAGEIFS('Daily Summary'!$M$5:$M$70,'Daily Summary'!$B$5:$B$70,$A6,'Daily Summary'!$C$5:$C$70,"Yes"),"") -> 2.5857143 | J6: =IFERROR(AVERAGEIFS('Daily Summary'!$P$5:$P$70,'Daily Summary'!$B$5:$B$70,$A6,'Daily Summary'!$C$5:$C$70,"Yes"),"") -> 6.6866667 | K6: =IFERROR(AVERAGEIFS('Daily Summary'!$Q$5:$Q$70,'Daily Summary'!$B$5:$B$70,$A6,'Daily Summary'!$C$5:$C$70,"Yes"),"") -> 8.71 | L6: =IFERROR(MOD(AVERAGEIFS('Daily Summary'!$S$5:$S$70,'Daily Summary'!$B$5:$B$70,$A6,'Daily Summary'!$C$5:$C$70,"Yes")/24+0.5,1),"") -> 0.030555556 | M6: =IFERROR(AVERAGEIFS('Daily Summary'!$T$5:$T$70,'Daily Summary'!$B$5:$B$70,$A6,'Daily Summary'!$C$5:$C$70,"Yes"),"") -> 0.30916667 | N6: =IF(OR(D6="",D5=""),"",D6-D5) | O6: =IF(OR(K6="",K5=""),"",K6-K5) -> -0.48166667 | P6: Aug 17
A7: 46258 | B7: =COUNTIFS('Daily Summary'!$B$5:$B$70,A7,'Daily Summary'!$C$5:$C$70,"Yes") -> 7 | C7: =IFERROR(AVERAGEIFS('Daily Summary'!$D$5:$D$70,'Daily Summary'!$B$5:$B$70,$A7,'Daily Summary'!$C$5:$C$70,"Yes"),"") -> 6 | D7: =IFERROR(AVERAGEIFS('Daily Summary'!$F$5:$F$70,'Daily Summary'!$B$5:$B$70,$A7,'Daily Summary'!$C$5:$C$70,"Yes"),"") -> 20.571429 | E7: =IFERROR(SUMIFS('Daily Summary'!$F$5:$F$70,'Daily Summary'!$B$5:$B$70,$A7,'Daily Summary'!$C$5:$C$70,"Yes")/SUMIFS('Daily Summary'!$E$5:$E$70,'Daily Summary'!$B$5:$B$70,$A7,'Daily Summary'!$C$5:$C$70,"Yes"),"") -> 4 | F7: =IFERROR(AVERAGEIFS('Daily Summary'!$H$5:$H$70,'Daily Summary'!$B$5:$B$70,$A7,'Daily Summary'!$C$5:$C$70,"Yes"),"") -> 3.8571429 | G7: =IFERROR(AVERAGEIFS('Daily Summary'!$I$5:$I$70,'Daily Summary'!$B$5:$B$70,$A7,'Daily Summary'!$C$5:$C$70,"Yes"),"") -> 0.85714286 | H7: =IFERROR(AVERAGEIFS('Daily Summary'!$L$5:$L$70,'Daily Summary'!$B$5:$B$70,$A7,'Daily Summary'!$C$5:$C$70,"Yes"),"") -> 3.5714286 | I7: =IFERROR(AVERAGEIFS('Daily Summary'!$M$5:$M$70,'Daily Summary'!$B$5:$B$70,$A7,'Daily Summary'!$C$5:$C$70,"Yes"),"") -> 3.0285714 | J7: =IFERROR(AVERAGEIFS('Daily Summary'!$P$5:$P$70,'Daily Summary'!$B$5:$B$70,$A7,'Daily Summary'!$C$5:$C$70,"Yes"),"") -> 6.6785714 | K7: =IFERROR(AVERAGEIFS('Daily Summary'!$Q$5:$Q$70,'Daily Summary'!$B$5:$B$70,$A7,'Daily Summary'!$C$5:$C$70,"Yes"),"") -> 9.7071429 | L7: =IFERROR(MOD(AVERAGEIFS('Daily Summary'!$S$5:$S$70,'Daily Summary'!$B$5:$B$70,$A7,'Daily Summary'!$C$5:$C$70,"Yes")/24+0.5,1),"") -> 0.054265873 | M7: =IFERROR(AVERAGEIFS('Daily Summary'!$T$5:$T$70,'Daily Summary'!$B$5:$B$70,$A7,'Daily Summary'!$C$5:$C$70,"Yes"),"") -> 0.28184524 | N7: =IF(OR(D7="",D6=""),"",D7-D6) | O7: =IF(OR(K7="",K6=""),"",K7-K6) -> 0.99714286 | P7: Aug 24
A8: 46265 | B8: =COUNTIFS('Daily Summary'!$B$5:$B$70,A8,'Daily Summary'!$C$5:$C$70,"Yes") -> 7 | C8: =IFERROR(AVERAGEIFS('Daily Summary'!$D$5:$D$70,'Daily Summary'!$B$5:$B$70,$A8,'Daily Summary'!$C$5:$C$70,"Yes"),"") -> 6.2857143 | D8: =IFERROR(AVERAGEIFS('Daily Summary'!$F$5:$F$70,'Daily Summary'!$B$5:$B$70,$A8,'Daily Summary'!$C$5:$C$70,"Yes"),"") -> 25.142857 | E8: =IFERROR(SUMIFS('Daily Summary'!$F$5:$F$70,'Daily Summary'!$B$5:$B$70,$A8,'Daily Summary'!$C$5:$C$70,"Yes")/SUMIFS('Daily Summary'!$E$5:$E$70,'Daily Summary'!$B$5:$B$70,$A8,'Daily Summary'!$C$5:$C$70,"Yes"),"") -> 4 | F8: =IFERROR(AVERAGEIFS('Daily Summary'!$H$5:$H$70,'Daily Summary'!$B$5:$B$70,$A8,'Daily Summary'!$C$5:$C$70,"Yes"),"") -> 4.4285714 | G8: =IFERROR(AVERAGEIFS('Daily Summary'!$I$5:$I$70,'Daily Summary'!$B$5:$B$70,$A8,'Daily Summary'!$C$5:$C$70,"Yes"),"") -> 1.5714286 | H8: =IFERROR(AVERAGEIFS('Daily Summary'!$L$5:$L$70,'Daily Summary'!$B$5:$B$70,$A8,'Daily Summary'!$C$5:$C$70,"Yes"),"") -> 3.1428571 | I8: =IFERROR(AVERAGEIFS('Daily Summary'!$M$5:$M$70,'Daily Summary'!$B$5:$B$70,$A8,'Daily Summary'!$C$5:$C$70,"Yes"),"") -> 2.352381 | J8: =IFERROR(AVERAGEIFS('Daily Summary'!$P$5:$P$70,'Daily Summary'!$B$5:$B$70,$A8,'Daily Summary'!$C$5:$C$70,"Yes"),"") -> 7.652381 | K8: =IFERROR(AVERAGEIFS('Daily Summary'!$Q$5:$Q$70,'Daily Summary'!$B$5:$B$70,$A8,'Daily Summary'!$C$5:$C$70,"Yes"),"") -> 10.004762 | L8: =IFERROR(MOD(AVERAGEIFS('Daily Summary'!$S$5:$S$70,'Daily Summary'!$B$5:$B$70,$A8,'Daily Summary'!$C$5:$C$70,"Yes")/24+0.5,1),"") -> 0.033234127 | M8: =IFERROR(AVERAGEIFS('Daily Summary'!$T$5:$T$70,'Daily Summary'!$B$5:$B$70,$A8,'Daily Summary'!$C$5:$C$70,"Yes"),"") -> 0.35208333 | N8: =IF(OR(D8="",D7=""),"",D8-D7) -> 4.5714286 | O8: =IF(OR(K8="",K7=""),"",K8-K7) -> 0.29761905 | P8: Aug 31
A9: 46272 | B9: =COUNTIFS('Daily Summary'!$B$5:$B$70,A9,'Daily Summary'!$C$5:$C$70,"Yes") -> 7 | C9: =IFERROR(AVERAGEIFS('Daily Summary'!$D$5:$D$70,'Daily Summary'!$B$5:$B$70,$A9,'Daily Summary'!$C$5:$C$70,"Yes"),"") -> 6.1428571 | D9: =IFERROR(AVERAGEIFS('Daily Summary'!$F$5:$F$70,'Daily Summary'!$B$5:$B$70,$A9,'Daily Summary'!$C$5:$C$70,"Yes"),"") -> 27.714286 | E9: =IFERROR(SUMIFS('Daily Summary'!$F$5:$F$70,'Daily Summary'!$B$5:$B$70,$A9,'Daily Summary'!$C$5:$C$70,"Yes")/SUMIFS('Daily Summary'!$E$5:$E$70,'Daily Summary'!$B$5:$B$70,$A9,'Daily Summary'!$C$5:$C$70,"Yes"),"") -> 4.5116279 | F9: =IFERROR(AVERAGEIFS('Daily Summary'!$H$5:$H$70,'Daily Summary'!$B$5:$B$70,$A9,'Daily Summary'!$C$5:$C$70,"Yes"),"") -> 5 | G9: =IFERROR(AVERAGEIFS('Daily Summary'!$I$5:$I$70,'Daily Summary'!$B$5:$B$70,$A9,'Daily Summary'!$C$5:$C$70,"Yes"),"") -> 1.7142857 | H9: =IFERROR(AVERAGEIFS('Daily Summary'!$L$5:$L$70,'Daily Summary'!$B$5:$B$70,$A9,'Daily Summary'!$C$5:$C$70,"Yes"),"") -> 2.7142857 | I9: =IFERROR(AVERAGEIFS('Daily Summary'!$M$5:$M$70,'Daily Summary'!$B$5:$B$70,$A9,'Daily Summary'!$C$5:$C$70,"Yes"),"") -> 3.2642857 | J9: =IFERROR(AVERAGEIFS('Daily Summary'!$P$5:$P$70,'Daily Summary'!$B$5:$B$70,$A9,'Daily Summary'!$C$5:$C$70,"Yes"),"") -> 6.7238095 | K9: =IFERROR(AVERAGEIFS('Daily Summary'!$Q$5:$Q$70,'Daily Summary'!$B$5:$B$70,$A9,'Daily Summary'!$C$5:$C$70,"Yes"),"") -> 9.9880952 | L9: =IFERROR(MOD(AVERAGEIFS('Daily Summary'!$S$5:$S$70,'Daily Summary'!$B$5:$B$70,$A9,'Daily Summary'!$C$5:$C$70,"Yes")/24+0.5,1),"") -> 0.031547619 | M9: =IFERROR(AVERAGEIFS('Daily Summary'!$T$5:$T$70,'Daily Summary'!$B$5:$B$70,$A9,'Daily Summary'!$C$5:$C$70,"Yes"),"") -> 0.31170635 | N9: =IF(OR(D9="",D8=""),"",D9-D8) -> 2.5714286 | O9: =IF(OR(K9="",K8=""),"",K9-K8) -> -0.016666667 | P9: Sep 7
A10: 46279 | B10: =COUNTIFS('Daily Summary'!$B$5:$B$70,A10,'Daily Summary'!$C$5:$C$70,"Yes") -> 7 | C10: =IFERROR(AVERAGEIFS('Daily Summary'!$D$5:$D$70,'Daily Summary'!$B$5:$B$70,$A10,'Daily Summary'!$C$5:$C$70,"Yes"),"") -> 5.8571429 | D10: =IFERROR(AVERAGEIFS('Daily Summary'!$F$5:$F$70,'Daily Summary'!$B$5:$B$70,$A10,'Daily Summary'!$C$5:$C$70,"Yes"),"") -> 29.714286 | E10: =IFERROR(SUMIFS('Daily Summary'!$F$5:$F$70,'Daily Summary'!$B$5:$B$70,$A10,'Daily Summary'!$C$5:$C$70,"Yes")/SUMIFS('Daily Summary'!$E$5:$E$70,'Daily Summary'!$B$5:$B$70,$A10,'Daily Summary'!$C$5:$C$70,"Yes"),"") -> 5.0731707 | F10: =IFERROR(AVERAGEIFS('Daily Summary'!$H$5:$H$70,'Daily Summary'!$B$5:$B$70,$A10,'Daily Summary'!$C$5:$C$70,"Yes"),"") -> 5 | G10: =IFERROR(AVERAGEIFS('Daily Summary'!$I$5:$I$70,'Daily Summary'!$B$5:$B$70,$A10,'Daily Summary'!$C$5:$C$70,"Yes"),"") -> 1.8571429 | H10: =IFERROR(AVERAGEIFS('Daily Summary'!$L$5:$L$70,'Daily Summary'!$B$5:$B$70,$A10,'Daily Summary'!$C$5:$C$70,"Yes"),"") -> 1.8571429 | I10: =IFERROR(AVERAGEIFS('Daily Summary'!$M$5:$M$70,'Daily Summary'!$B$5:$B$70,$A10,'Daily Summary'!$C$5:$C$70,"Yes"),"") -> 2.5238095 | J10: =IFERROR(AVERAGEIFS('Daily Summary'!$P$5:$P$70,'Daily Summary'!$B$5:$B$70,$A10,'Daily Summary'!$C$5:$C$70,"Yes"),"") -> 6.85 | K10: =IFERROR(AVERAGEIFS('Daily Summary'!$Q$5:$Q$70,'Daily Summary'!$B$5:$B$70,$A10,'Daily Summary'!$C$5:$C$70,"Yes"),"") -> 9.3738095 | L10: =IFERROR(MOD(AVERAGEIFS('Daily Summary'!$S$5:$S$70,'Daily Summary'!$B$5:$B$70,$A10,'Daily Summary'!$C$5:$C$70,"Yes")/24+0.5,1),"") -> 0.042956349 | M10: =IFERROR(AVERAGEIFS('Daily Summary'!$T$5:$T$70,'Daily Summary'!$B$5:$B$70,$A10,'Daily Summary'!$C$5:$C$70,"Yes"),"") -> 0.32837302 | N10: =IF(OR(D10="",D9=""),"",D10-D9) -> 2 | O10: =IF(OR(K10="",K9=""),"",K10-K9) -> -0.61428571 | P10: Sep 14
A11: 46286 | B11: =COUNTIFS('Daily Summary'!$B$5:$B$70,A11,'Daily Summary'!$C$5:$C$70,"Yes") -> 7 | C11: =IFERROR(AVERAGEIFS('Daily Summary'!$D$5:$D$70,'Daily Summary'!$B$5:$B$70,$A11,'Daily Summary'!$C$5:$C$70,"Yes"),"") -> 5.5714286 | D11: =IFERROR(AVERAGEIFS('Daily Summary'!$F$5:$F$70,'Daily Summary'!$B$5:$B$70,$A11,'Daily Summary'!$C$5:$C$70,"Yes"),"") -> 28 | E11: =IFERROR(SUMIFS('Daily Summary'!$F$5:$F$70,'Daily Summary'!$B$5:$B$70,$A11,'Daily Summary'!$C$5:$C$70,"Yes")/SUMIFS('Daily Summary'!$E$5:$E$70,'Daily Summary'!$B$5:$B$70,$A11,'Daily Summary'!$C$5:$C$70,"Yes"),"") -> 5.025641 | F11: =IFERROR(AVERAGEIFS('Daily Summary'!$H$5:$H$70,'Daily Summary'!$B$5:$B$70,$A11,'Daily Summary'!$C$5:$C$70,"Yes"),"") -> 5 | G11: =IFERROR(AVERAGEIFS('Daily Summary'!$I$5:$I$70,'Daily Summary'!$B$5:$B$70,$A11,'Daily Summary'!$C$5:$C$70,"Yes"),"") -> 1.5714286 | H11: =IFERROR(AVERAGEIFS('Daily Summary'!$L$5:$L$70,'Daily Summary'!$B$5:$B$70,$A11,'Daily Summary'!$C$5:$C$70,"Yes"),"") -> 3.7142857 | I11: =IFERROR(AVERAGEIFS('Daily Summary'!$M$5:$M$70,'Daily Summary'!$B$5:$B$70,$A11,'Daily Summary'!$C$5:$C$70,"Yes"),"") -> 3.2952381 | J11: =IFERROR(AVERAGEIFS('Daily Summary'!$P$5:$P$70,'Daily Summary'!$B$5:$B$70,$A11,'Daily Summary'!$C$5:$C$70,"Yes"),"") -> 7.1638889 | K11: =IFERROR(AVERAGEIFS('Daily Summary'!$Q$5:$Q$70,'Daily Summary'!$B$5:$B$70,$A11,'Daily Summary'!$C$5:$C$70,"Yes"),"") -> 10.369444 | L11: =IFERROR(MOD(AVERAGEIFS('Daily Summary'!$S$5:$S$70,'Daily Summary'!$B$5:$B$70,$A11,'Daily Summary'!$C$5:$C$70,"Yes")/24+0.5,1),"") -> 0.023611111 | M11: =IFERROR(AVERAGEIFS('Daily Summary'!$T$5:$T$70,'Daily Summary'!$B$5:$B$70,$A11,'Daily Summary'!$C$5:$C$70,"Yes"),"") -> 0.32210648 | N11: =IF(OR(D11="",D10=""),"",D11-D10) -> -1.7142857 | O11: =IF(OR(K11="",K10=""),"",K11-K10) -> 0.99563492 | P11: Sep 21
A12: 46293 | B12: =COUNTIFS('Daily Summary'!$B$5:$B$70,A12,'Daily Summary'!$C$5:$C$70,"Yes") -> 7 | C12: =IFERROR(AVERAGEIFS('Daily Summary'!$D$5:$D$70,'Daily Summary'!$B$5:$B$70,$A12,'Daily Summary'!$C$5:$C$70,"Yes"),"") -> 5.5714286 | D12: =IFERROR(AVERAGEIFS('Daily Summary'!$F$5:$F$70,'Daily Summary'!$B$5:$B$70,$A12,'Daily Summary'!$C$5:$C$70,"Yes"),"") -> 28.142857 | E12: =IFERROR(SUMIFS('Daily Summary'!$F$5:$F$70,'Daily Summary'!$B$5:$B$70,$A12,'Daily Summary'!$C$5:$C$70,"Yes")/SUMIFS('Daily Summary'!$E$5:$E$70,'Daily Summary'!$B$5:$B$70,$A12,'Daily Summary'!$C$5:$C$70,"Yes"),"") -> 5.0512821 | F12: =IFERROR(AVERAGEIFS('Daily Summary'!$H$5:$H$70,'Daily Summary'!$B$5:$B$70,$A12,'Daily Summary'!$C$5:$C$70,"Yes"),"") -> 4.7142857 | G12: =IFERROR(AVERAGEIFS('Daily Summary'!$I$5:$I$70,'Daily Summary'!$B$5:$B$70,$A12,'Daily Summary'!$C$5:$C$70,"Yes"),"") -> 1.1428571 | H12: =IFERROR(AVERAGEIFS('Daily Summary'!$L$5:$L$70,'Daily Summary'!$B$5:$B$70,$A12,'Daily Summary'!$C$5:$C$70,"Yes"),"") -> 3.5714286 | I12: =IFERROR(AVERAGEIFS('Daily Summary'!$M$5:$M$70,'Daily Summary'!$B$5:$B$70,$A12,'Daily Summary'!$C$5:$C$70,"Yes"),"") -> 2.8642857 | J12: =IFERROR(AVERAGEIFS('Daily Summary'!$P$5:$P$70,'Daily Summary'!$B$5:$B$70,$A12,'Daily Summary'!$C$5:$C$70,"Yes"),"") -> 7.2333333 | K12: =IFERROR(AVERAGEIFS('Daily Summary'!$Q$5:$Q$70,'Daily Summary'!$B$5:$B$70,$A12,'Daily Summary'!$C$5:$C$70,"Yes"),"") -> 10.097619 | L12: =IFERROR(MOD(AVERAGEIFS('Daily Summary'!$S$5:$S$70,'Daily Summary'!$B$5:$B$70,$A12,'Daily Summary'!$C$5:$C$70,"Yes")/24+0.5,1),"") -> 0.053075397 | M12: =IFERROR(AVERAGEIFS('Daily Summary'!$T$5:$T$70,'Daily Summary'!$B$5:$B$70,$A12,'Daily Summary'!$C$5:$C$70,"Yes"),"") -> 0.35446429 | N12: =IF(OR(D12="",D11=""),"",D12-D11) -> 0.14285714 | O12: =IF(OR(K12="",K11=""),"",K12-K11) -> -0.2718254 | P12: Sep 28
A13: 46300 | B13: =COUNTIFS('Daily Summary'!$B$5:$B$70,A13,'Daily Summary'!$C$5:$C$70,"Yes") -> 7 | C13: =IFERROR(AVERAGEIFS('Daily Summary'!$D$5:$D$70,'Daily Summary'!$B$5:$B$70,$A13,'Daily Summary'!$C$5:$C$70,"Yes"),"") -> 5.7142857 | D13: =IFERROR(AVERAGEIFS('Daily Summary'!$F$5:$F$70,'Daily Summary'!$B$5:$B$70,$A13,'Daily Summary'!$C$5:$C$70,"Yes"),"") -> 29.428571 | E13: =IFERROR(SUMIFS('Daily Summary'!$F$5:$F$70,'Daily Summary'!$B$5:$B$70,$A13,'Daily Summary'!$C$5:$C$70,"Yes")/SUMIFS('Daily Summary'!$E$5:$E$70,'Daily Summary'!$B$5:$B$70,$A13,'Daily Summary'!$C$5:$C$70,"Yes"),"") -> 5.15 | F13: =IFERROR(AVERAGEIFS('Daily Summary'!$H$5:$H$70,'Daily Summary'!$B$5:$B$70,$A13,'Daily Summary'!$C$5:$C$70,"Yes"),"") -> 4.4285714 | G13: =IFERROR(AVERAGEIFS('Daily Summary'!$I$5:$I$70,'Daily Summary'!$B$5:$B$70,$A13,'Daily Summary'!$C$5:$C$70,"Yes"),"") -> 1 | H13: =IFERROR(AVERAGEIFS('Daily Summary'!$L$5:$L$70,'Daily Summary'!$B$5:$B$70,$A13,'Daily Summary'!$C$5:$C$70,"Yes"),"") -> 4.2857143 | I13: =IFERROR(AVERAGEIFS('Daily Summary'!$M$5:$M$70,'Daily Summary'!$B$5:$B$70,$A13,'Daily Summary'!$C$5:$C$70,"Yes"),"") -> 3.047619 | J13: =IFERROR(AVERAGEIFS('Daily Summary'!$P$5:$P$70,'Daily Summary'!$B$5:$B$70,$A13,'Daily Summary'!$C$5:$C$70,"Yes"),"") -> 7.7952381 | K13: =IFERROR(AVERAGEIFS('Daily Summary'!$Q$5:$Q$70,'Daily Summary'!$B$5:$B$70,$A13,'Daily Summary'!$C$5:$C$70,"Yes"),"") -> 10.842857 | L13: =IFERROR(MOD(AVERAGEIFS('Daily Summary'!$S$5:$S$70,'Daily Summary'!$B$5:$B$70,$A13,'Daily Summary'!$C$5:$C$70,"Yes")/24+0.5,1),"") -> 0.03422619 | M13: =IFERROR(AVERAGEIFS('Daily Summary'!$T$5:$T$70,'Daily Summary'!$B$5:$B$70,$A13,'Daily Summary'!$C$5:$C$70,"Yes"),"") -> 0.35902778 | N13: =IF(OR(D13="",D12=""),"",D13-D12) -> 1.2857143 | O13: =IF(OR(K13="",K12=""),"",K13-K12) -> 0.7452381 | P13: Oct 5
A14: 46307 | B14: =COUNTIFS('Daily Summary'!$B$5:$B$70,A14,'Daily Summary'!$C$5:$C$70,"Yes") -> 6 | C14: =IFERROR(AVERAGEIFS('Daily Summary'!$D$5:$D$70,'Daily Summary'!$B$5:$B$70,$A14,'Daily Summary'!$C$5:$C$70,"Yes"),"") -> 5.6666667 | D14: =IFERROR(AVERAGEIFS('Daily Summary'!$F$5:$F$70,'Daily Summary'!$B$5:$B$70,$A14,'Daily Summary'!$C$5:$C$70,"Yes"),"") -> 29.166667 | E14: =IFERROR(SUMIFS('Daily Summary'!$F$5:$F$70,'Daily Summary'!$B$5:$B$70,$A14,'Daily Summary'!$C$5:$C$70,"Yes")/SUMIFS('Daily Summary'!$E$5:$E$70,'Daily Summary'!$B$5:$B$70,$A14,'Daily Summary'!$C$5:$C$70,"Yes"),"") -> 5.1470588 | F14: =IFERROR(AVERAGEIFS('Daily Summary'!$H$5:$H$70,'Daily Summary'!$B$5:$B$70,$A14,'Daily Summary'!$C$5:$C$70,"Yes"),"") -> 4.3333333 | G14: =IFERROR(AVERAGEIFS('Daily Summary'!$I$5:$I$70,'Daily Summary'!$B$5:$B$70,$A14,'Daily Summary'!$C$5:$C$70,"Yes"),"") -> 1.1666667 | H14: =IFERROR(AVERAGEIFS('Daily Summary'!$L$5:$L$70,'Daily Summary'!$B$5:$B$70,$A14,'Daily Summary'!$C$5:$C$70,"Yes"),"") -> 3.8333333 | I14: =IFERROR(AVERAGEIFS('Daily Summary'!$M$5:$M$70,'Daily Summary'!$B$5:$B$70,$A14,'Daily Summary'!$C$5:$C$70,"Yes"),"") -> 3.15 | J14: =IFERROR(AVERAGEIFS('Daily Summary'!$P$5:$P$70,'Daily Summary'!$B$5:$B$70,$A14,'Daily Summary'!$C$5:$C$70,"Yes"),"") -> 7.0916667 | K14: =IFERROR(AVERAGEIFS('Daily Summary'!$Q$5:$Q$70,'Daily Summary'!$B$5:$B$70,$A14,'Daily Summary'!$C$5:$C$70,"Yes"),"") -> 10.241667 | L14: =IFERROR(MOD(AVERAGEIFS('Daily Summary'!$S$5:$S$70,'Daily Summary'!$B$5:$B$70,$A14,'Daily Summary'!$C$5:$C$70,"Yes")/24+0.5,1),"") -> 0.046064815 | M14: =IFERROR(AVERAGEIFS('Daily Summary'!$T$5:$T$70,'Daily Summary'!$B$5:$B$70,$A14,'Daily Summary'!$C$5:$C$70,"Yes"),"") -> 0.34155093 | N14: =IF(OR(D14="",D13=""),"",D14-D13) -> -0.26190476 | O14: =IF(OR(K14="",K13=""),"",K14-K13) -> -0.60119048 | P14: Oct 12

Sheet Raw Log
A1: Raw Log
A2: Every event logged in the app, in New York time. Baby day = the day it counts toward (days run 4 AM to 4 AM).
A4: Date & time | B4: Event | C4: Ounces | D4: Diaper type | E4: Note | F4: Baby day
A5: 46245.479 | B5: Diaper | F5: =INT(A5-4/24) -> 46245
A6: 46248.792 | B6: Medicine | E6: 4pm dose given late | F6: =INT(A6-4/24) -> 46248
A7: 46248.854 | B7: Feed | E7: seed | F7: =INT(A7-4/24) -> 46248
A8: 46248.934 | B8: Diaper | F8: =INT(A8-4/24) -> 46248
A9: 46248.96 | B9: Feed | F9: =INT(A9-4/24) -> 46248
A10: 46249.007 | B10: Medicine | F10: =INT(A10-4/24) -> 46248
A11: 46249.025 | B11: Bedtime | F11: =INT(A11-4/24) -> 46248
A12: 46249.312 | B12: Wake up | F12: =INT(A12-4/24) -> 46249
A13: 46249.328 | B13: Medicine | F13: =INT(A13-4/24) -> 46249
A14: 46249.342 | B14: Feed | F14: =INT(A14-4/24) -> 46249
A15: 46249.342 | B15: Diaper | F15: =INT(A15-4/24) -> 46249
A16: 46249.369 | B16: Nap start | F16: =INT(A16-4/24) -> 46249
A17: 46249.409 | B17: Nap end | F17: =INT(A17-4/24) -> 46249
A18: 46249.438 | B18: Feed | F18: =INT(A18-4/24) -> 46249
A19: 46249.451 | B19: Diaper | F19: =INT(A19-4/24) -> 46249
... A253: 46258.998 | B253: Nap end | F253: =INT(A253-4/24) -> 46258
A254: 46258.998 | B254: Diaper | D254: Pee | F254: =INT(A254-4/24) -> 46258
A255: 46259.002 | B255: Medicine | F255: =INT(A255-4/24) -> 46258
A256: 46259.002 | B256: Feed | C256: 4 | F256: =INT(A256-4/24) -> 46258
A257: 46259.021 | B257: Bedtime | F257: =INT(A257-4/24) -> 46258
A258: 46259.293 | B258: Wake up | F258: =INT(A258-4/24) -> 46259
A259: 46259.297 | B259: Diaper | D259: Pee | F259: =INT(A259-4/24) -> 46259
A260: 46259.308 | B260: Feed | C260: 4 | F260: =INT(A260-4/24) -> 46259
A261: 46259.337 | B261: Medicine | F261: =INT(A261-4/24) -> 46259
A262: 46259.345 | B262: Nap start | F262: =INT(A262-4/24) -> 46259
A263: 46259.379 | B263: Nap end | F263: =INT(A263-4/24) -> 46259
A264: 46259.414 | B264: Diaper | D264: Pee | F264: =INT(A264-4/24) -> 46259
A265: 46259.442 | B265: Feed | C265: 4 | F265: =INT(A265-4/24) -> 46259
A266: 46259.466 | B266: Nap start | F266: =INT(A266-4/24) -> 46259
A267: 46259.479 | B267: Nap end | F267: =INT(A267-4/24) -> 46259
A268: 46259.553 | B268: Nap start | F268: =INT(A268-4/24) -> 46259
A269: 46259.554 | B269: Nap end | F269: =INT(A269-4/24) -> 46259
A270: 46259.567 | B270: Feed | C270: 4 | F270: =INT(A270-4/24) -> 46259
A271: 46259.63 | B271: Diaper | D271: Pee | F271: =INT(A271-4/24) -> 46259
A272: 46259.632 | B272: Nap start | F272: =INT(A272-4/24) -> 46259
A273: 46259.667 | B273: Nap end | F273: =INT(A273-4/24) -> 46259
A274: 46259.677 | B274: Medicine | F274: =INT(A274-4/24) -> 46259
...

Sheet Sleep Detail
A1: Sleep Detail
A2: Every nap and night, paired from the start and end taps. "Awake before" = time awake since the previous sleep ended.
A4: Baby day | B4: Type | C4: Fell asleep | D4: Woke up | E4: Length (hrs) | F4: Awake before (hrs)
A5: =INT(C5-4/24) -> 46248 | B5: Night | C5: 46249.025 | D5: 46249.312 | E5: =(D5-C5)*24 -> 6.9 | F5: =""
A6: =INT(C6-4/24) -> 46249 | B6: Nap | C6: 46249.369 | D6: 46249.409 | E6: =(D6-C6)*24 -> 0.95 | F6: =IF((C6-D5)*24>12,"",(C6-D5)*24) -> 1.3666667
A7: =INT(C7-4/24) -> 46249 | B7: Nap | C7: 46249.469 | D7: 46249.501 | E7: =(D7-C7)*24 -> 0.76666667 | F7: =IF((C7-D6)*24>12,"",(C7-D6)*24) -> 1.45
A8: =INT(C8-4/24) -> 46249 | B8: Nap | C8: 46249.61 | D8: 46249.631 | E8: =(D8-C8)*24 -> 0.5 | F8: =IF((C8-D7)*24>12,"",(C8-D7)*24) -> 2.6
A9: =INT(C9-4/24) -> 46249 | B9: Nap | C9: 46249.682 | D9: 46249.712 | E9: =(D9-C9)*24 -> 0.71666667 | F9: =IF((C9-D8)*24>12,"",(C9-D8)*24) -> 1.2333333
A10: =INT(C10-4/24) -> 46249 | B10: Nap | C10: 46249.877 | D10: 46249.9 | E10: =(D10-C10)*24 -> 0.55 | F10: =IF((C10-D9)*24>12,"",(C10-D9)*24) -> 3.9666667
A11: =INT(C11-4/24) -> 46249 | B11: Nap | C11: 46249.966 | D11: 46250.017 | E11: =(D11-C11)*24 -> 1.2166667 | F11: =IF((C11-D10)*24>12,"",(C11-D10)*24) -> 1.5833333
A12: =INT(C12-4/24) -> 46249 | B12: Night | C12: 46250.062 | D12: 46250.254 | E12: =(D12-C12)*24 -> 4.6 | F12: =IF((C12-D11)*24>12,"",(C12-D11)*24) -> 1.1
A13: =INT(C13-4/24) -> 46250 | B13: Nap | C13: 46250.753 | D13: 46250.81 | E13: =(D13-C13)*24 -> 1.35 | F13: =IF((C13-D12)*24>12,"",(C13-D12)*24) -> 11.983333
A14: =INT(C14-4/24) -> 46250 | B14: Night | C14: 46251.012 | D14: 46251.334 | E14: =(D14-C14)*24 -> 7.7333333 | F14: =IF((C14-D13)*24>12,"",(C14-D13)*24) -> 4.85
A15: =INT(C15-4/24) -> 46251 | B15: Nap | C15: 46251.413 | D15: 46251.426 | E15: =(D15-C15)*24 -> 0.31666667 | F15: =IF((C15-D14)*24>12,"",(C15-D14)*24) -> 1.9
A16: =INT(C16-4/24) -> 46251 | B16: Nap | C16: 46251.51 | D16: 46251.522 | E16: =(D16-C16)*24 -> 0.26666667 | F16: =IF((C16-D15)*24>12,"",(C16-D15)*24) -> 2.0166667
A17: =INT(C17-4/24) -> 46251 | B17: Nap | C17: 46251.597 | D17: 46251.61 | E17: =(D17-C17)*24 -> 0.31666667 | F17: =IF((C17-D16)*24>12,"",(C17-D16)*24) -> 1.8166667
... A285: =INT(C285-4/24) -> 46313 | B285: Nap | C285: 46313.635 | D285: 46313.662 | E285: =(D285-C285)*24 -> 0.65 | F285: =IF((C285-D284)*24>12,"",(C285-D284)*24) -> 1.9333333

Sheet Data Notes
A1: Data Notes
